Workbook

Sheet README
A1: CPRT Intermediate — data and formulas to copy into "CPRT Model"
A2: Built 2026-09-15 by scripts/build_intermediate_xlsx.py from the committed CSVs in data/csv/. Rebuild after any data update; do not hand-edit Data_* tabs.
A4: HOW TO USE
A5: Copy whole sheets, not cells | B5: Right-click a tab → Move or Copy → To book: CPRT Model → tick Create a copy. Copy the tabs a formula sheet depends on FIRST (Inputs, Data_Sales, Data_EPA_Survival, Data_EPA_Miles, Data_CCC_Targets, then Survival, Fleet, FleetByAge, Curves, then TLF_Roll / Calibration). References are explicit sheet names, no named ranges, so they survive the copy as long as the tab names are unchanged.
A6: Colour legend | B6: BLUE = hard-coded input · BLACK = formula · GREEN = link to another sheet · YELLOW fill = calibrated parameter (fitted; reproducible on Calibration / Spread_Reg / RPU_Reg).
A7: One assumption per cell | B7: Every parameter lives once, on Inputs. Formula tabs never contain a typed number except the fixed 2024 cross-section on Calibration and Curves I:K.
A8: Check before you trust | B8: Checks tab must read OK everywhere after Excel recalculates (it does on open). If a check FAILs, a reference broke in the copy.
A10: TAB INDEX
A11: Inputs | B11: All parameters (survival stretch, R/P, exposure, future sales, anchors) + the k(t) path by year.
A12: Data_Sales | B12: Cohort sizes: new light-vehicle sales by model year, cars and light trucks, 1970–2030 (2026+ from Inputs).
A13: Data_EPA_Survival | B13: EPA survival schedule by age (ORNL TEDB Ed.40 T3.15). Data_EPA_Miles: EPA miles by age (T3.14).
A14: Data_CCC_Targets | B14: The CCC statistics R and P are fitted to (FIT), tested against (OOS), and the fleet-count anchors (S), each with its verbatim quote and page.
A15: Survival | B15: S(a,t) = EPA(a/k(t)) for cars and light trucks, ages 0–45 × years 2013–2030.
A16: Fleet | B16: Vehicles on the road by model year × calendar year (thousands). Row 68 = VIO.
A17: FleetByAge | B17: Same fleet re-indexed by age; VIO, share 7+/15+, count ≤6, average age.
A18: Curves | B18: R(a), P(a), miles by age, flags; the 7+ vs 0–6 miles/coverage decomposition.
A19: Calibration | B19: Solver set-up: five parameters → eight CCC 2024 statistics → LOSS. Instructions on the sheet.
A20: TLF_Roll | B20: Baseline TLF from demographics by year, its YoY drift, claim/TL age mix, and the out-of-sample checks vs CCC 2019/2020/2025.
A21: Spread_Reg | B21: ΔTLF = a + b·spread(t−1): pairs built by formula from Data_Spread and Data_CCC_TLF_Quarterly; SLOPE/INTERCEPT/RSQ; prediction and the live 2Q26 test.
A22: RPU_Reg | B22: ASP ~ used-car CPI by fiscal quarter (formulas on Data_CPI, Data_ReportedUnits); service and total RPU ~ ASP (Data_Elasticity); the chain calculator.
... A27: NOT IN THIS WORKBOOK | B27: Licensed material (S&P transcripts, Stephens preview, SOLS model) and the IHS-sourced ORNL tables (3.11/3.12/3.13, "further reproduction prohibited") — cited by table number only. Lot-level sitemap rows (1.3M) — in data/cprt.db.

Sheet Inputs
A1: Inputs — every parameter of the fleet roll in one place
A2: BLUE = hard-coded input (change freely) · YELLOW = calibrated (fitted on the Calibration tab / scripts/age_curves.py; copy new Solver results here) · model tabs reference ONLY this sheet for parameters.
A3: Parameter | B3: Value | C3: Source / note
A4: Survival stretch k, cars, 2013 | B4: 1.064 | C4: fitted to the IHS/Polk 2013 census of cars by single year of age (ORNL TEDB40 T3.11); S_k(a)=S_EPA(a/k). docs/AGE_CURVES.md §2.2
A5: Survival stretch k, light trucks, 2013 | B5: 0.92 | C5: fitted to the IHS 2013 census of trucks (T3.12, includes heavy). §2.2
A6: k multiplier by drift-end year | B6: 1.194 | C6: fitted so the 2024 roll hits VIO anchor and 66% aged 7+. 289M anchor is unverified (from memory); Experian 292.1M (on disk) gives 1.204 — same downstream. §2.4
A7: Drift start year | B7: 2013 | C7: k = 2013 value up to here
A8: Drift end year | B8: 2024 | C8: k reaches k_2013 × multiplier here; FLAT after (base case). Sensitivity: keep drifting
A9: Exposure factor, age 0 | B9: 0.5 | C9: a model-year-t vehicle is on the road ~half of calendar year t. Necessary: without it the ≤3-yr repairable share fits at 36% vs CCC ~30%. §3.2
A10: R kink age | B10: 6 | C10: R is flat through this age (a free 0–6 slope is not identified by the CCC targets). §3.3
A11: R slope after kink (per year of age) | B11: 0.09027 | C11: R(a) = e(a)·exp(−slope·max(a−kink,0)). Solver-fitted on Calibration tab. §3.3
A12: P floor (pmin) | B12: 0.0483 | C12: P(a) = pmin + (pmax−pmin)/(1+exp(−(a−mid)/width)). Solver-fitted. §4.3
A13: P ceiling (pmax) | B13: 0.4804
A14: P midpoint age (mid) | B14: 9.216
A15: P width (yrs) | B15: 3.726
A16: Future new-vehicle sales, cars (thousands per year, 2026+) | B16: 2764.4 | C16: ASSUMED = 2025 level (Data_Sales). Flex for a sales-recovery case
A17: Future new-vehicle sales, light trucks (thousands per year, 2026+) | B17: 13090.5 | C17: ASSUMED = 2025 level
A18: VIO anchor, end-2024 (M light vehicles) | B18: 289 | C18: S&P Global Mobility 2025 avg-age release — NOT ON DISK, confirm; Experian Q3-2024 = 292.1M (Crash Course 2025/Q1)
A19: Share aged 7+ anchor, 2024 | B19: 0.66 | C19: '66% of vehicles in operation are seven years or older' — S&P via CCC Crash Course 2024/Q4
A22: Survival stretch by calendar year (formulas)
A23: Year | C23: 2013 | D23: 2014 | E23: 2015 | F23: 2016 | G23: 2017 | H23: 2018 | I23: 2019 | J23: 2020 | K23: 2021 | L23: 2022 | M23: 2023 | N23: 2024 | O23: 2025 | P23: 2026 | Q23: 2027 | R23: 2028 | S23: 2029 | T23: 2030
A24: k multiplier | C24: =1+($B$6-1)*MIN(MAX(C23-$B$7,0),$B$8-$B$7)/($B$8-$B$7) | D24: =1+($B$6-1)*MIN(MAX(D23-$B$7,0),$B$8-$B$7)/($B$8-$B$7) | E24: =1+($B$6-1)*MIN(MAX(E23-$B$7,0),$B$8-$B$7)/($B$8-$B$7) | F24: =1+($B$6-1)*MIN(MAX(F23-$B$7,0),$B$8-$B$7)/($B$8-$B$7) | G24: =1+($B$6-1)*MIN(MAX(G23-$B$7,0),$B$8-$B$7)/($B$8-$B$7) | H24: =1+($B$6-1)*MIN(MAX(H23-$B$7,0),$B$8-$B$7)/($B$8-$B$7) | I24: =1+($B$6-1)*MIN(MAX(I23-$B$7,0),$B$8-$B$7)/($B$8-$B$7) | J24: =1+($B$6-1)*MIN(MAX(J23-$B$7,0),$B$8-$B$7)/($B$8-$B$7) | ... T24: =1+($B$6-1)*MIN(MAX(T23-$B$7,0),$B$8-$B$7)/($B$8-$B$7)
A25: k cars | C25: =$B$4*C24 | D25: =$B$4*D24 | E25: =$B$4*E24 | F25: =$B$4*F24 | G25: =$B$4*G24 | H25: =$B$4*H24 | I25: =$B$4*I24 | J25: =$B$4*J24 | ... T25: =$B$4*T24
A26: k light trucks | C26: =$B$5*C24 | D26: =$B$5*D24 | E26: =$B$5*E24 | F26: =$B$5*F24 | G26: =$B$5*G24 | H26: =$B$5*H24 | I26: =$B$5*I24 | J26: =$B$5*J24 | ... T26: =$B$5*T24
A28: Sensitivity idea: set B8 = 2030 to let survival keep improving; set B6 = 1.0 for the raw EPA schedule. Baseline TLF drift moves 0.05–0.18pp/yr across that range; P buckets do not move. §6

Sheet Data_Sales
A1: Cohort sizes — new light-vehicle sales by model year (thousands of vehicles)
A2: Cohort sizes for the fleet roll. 1970-2021 Ward's via ORNL TEDB Ed.40 Table 3.6; 2022-2025 FRED TOTALNSA (light vehicles) and LTRUCKNSA (light trucks), NSA monthly summed by calendar year (fetched 2026-09-14), | rescaled to Ward's basis using the 2021 overlap (cars x0.8789, light trucks x0.9675); heavy trucks 2022-25 = FRED HTRUCKSNSA (BEA, >14,000 lb) x1.823 to Ward's >10,000 lb basis — estimates, used only for the 2013 truck-census check.
A3: Unit: thousands of vehicles (8,321 = 8,321,000 cars). Ward's reports to the single vehicle, so the source carries decimals (e.g. 8,720.3); they are kept in the cells and hidden by the format. Ward's via ORNL TEDB Ed.40 Table 3.6 for 1970–2021; FRED TOTALNSA / LTRUCKNSA / HTRUCKSNSA rescaled to Ward's basis on the 2021 overlap for 2022–2025 (estimates — the decimals there mean nothing); 2026+ = Inputs (green). Heavy trucks (>10,000 lb) are NOT in the fleet roll; the column exists for the 2013 census check only. data/csv/light_vehicle_sales_by_year.csv
A4: model year | B4: cars (thousands) | C4: light trucks (thousands) | D4: heavy trucks (thousands) | E4: source
A5: 1970 | B5: 8321 | C5: 1457 | D5: 334 | E5: Ward's (ORNL TEDB40 T3.6)
A6: 1971 | B6: 10144 | C6: 1673 | D6: 340 | E6: Ward's (ORNL TEDB40 T3.6)
A7: 1972 | B7: 10800.6 | C7: 2097 | D7: 438 | E7: Ward's (ORNL TEDB40 T3.6)
A8: 1973 | B8: 11276 | C8: 2512 | D8: 497 | E8: Ward's (ORNL TEDB40 T3.6)
A9: 1974 | B9: 8720.3 | C9: 2163 | D9: 424 | E9: Ward's (ORNL TEDB40 T3.6)
A10: 1975 | B10: 8485.8 | C10: 2053 | D10: 298 | E10: Ward's (ORNL TEDB40 T3.6)
A11: 1976 | B11: 9956.8 | C11: 2719 | D11: 324 | E11: Ward's (ORNL TEDB40 T3.6)
A12: 1977 | B12: 11003.6 | C12: 3109 | D12: 376 | E12: Ward's (ORNL TEDB40 T3.6)
A13: 1978 | B13: 11107 | C13: 3474 | D13: 441 | E13: Ward's (ORNL TEDB40 T3.6)
A14: 1979 | B14: 10512 | C14: 2845 | D14: 391 | E14: Ward's (ORNL TEDB40 T3.6)
A15: 1980 | B15: 8948.8 | C15: 1960 | D15: 271 | E15: Ward's (ORNL TEDB40 T3.6)
A16: 1981 | B16: 8488.4 | C16: 1746 | D16: 226 | E16: Ward's (ORNL TEDB40 T3.6)
... A60: 2025 | B60: 2764.4 | C60: 13090.5 | D60: 758.9 | E60: FRED TOTALNSA/LTRUCKNSA/HTRUCKSNSA x Ward's-basis scale
A61: 2026 | B61: =Inputs!$B$16 | C61: =Inputs!$B$17 | E61: ASSUMED — Inputs B16/B17; heavy trucks not modelled (outside the light-vehicle roll)
A62: 2027 | B62: =Inputs!$B$16 | C62: =Inputs!$B$17 | E62: ASSUMED — Inputs B16/B17; heavy trucks not modelled (outside the light-vehicle roll)
A63: 2028 | B63: =Inputs!$B$16 | C63: =Inputs!$B$17 | E63: ASSUMED — Inputs B16/B17; heavy trucks not modelled (outside the light-vehicle roll)
A64: 2029 | B64: =Inputs!$B$16 | C64: =Inputs!$B$17 | E64: ASSUMED — Inputs B16/B17; heavy trucks not modelled (outside the light-vehicle roll)
A65: 2030 | B65: =Inputs!$B$16 | C65: =Inputs!$B$17 | E65: ASSUMED — Inputs B16/B17; heavy trucks not modelled (outside the light-vehicle roll)

Sheet Data_EPA_Survival
A1: EPA survival rates by vehicle age — cars and light trucks
A2: ORNL Transportation Energy Data Book Ed.40 (June 2022) spreadsheets, https://tedb.ornl.gov/wp-content/uploads/2022/06/TEDB_40_Spreadsheets_06012022.zip (robots-open, fetched 2026-09-14) | Table 3.15 (Table3_15_01312022.xlsx): EPA estimated survival rates by vehicle age, cars and light trucks (MY2015 rulemaking schedules)
A3: Primary: U.S. EPA, Draft Technical Assessment Report, Midterm Evaluation of LD GHG / CAFE Standards MY2022–2025, EPA-420-D-16-900, July 2016 — republished as ORNL Transportation Energy Data Book Ed.40 Table 3.15. Values verbatim.
A4: age | B4: survival_cars | C4: survival_light_trucks
A5: 0 | B5: 1 | C5: 1
A6: 1 | B6: 0.997 | C6: 0.991
A7: 2 | B7: 0.994 | C7: 0.982
A8: 3 | B8: 0.991 | C8: 0.973
A9: 4 | B9: 0.984 | C9: 0.96
A10: 5 | B10: 0.974 | C10: 0.941
A11: 6 | B11: 0.961 | C11: 0.919
A12: 7 | B12: 0.942 | C12: 0.891
A13: 8 | B13: 0.92 | C13: 0.859
A14: 9 | B14: 0.893 | C14: 0.823
A15: 10 | B15: 0.862 | C15: 0.784
A16: 11 | B16: 0.826 | C16: 0.741
... A36: 31 | B36: 0.002 | C36: 0.027

Sheet Data_CCC_Targets
A1: CCC Crash Course statistics used to fit and test R(age) and P(age)
A2: Quotes verbatim from the ungated report pages (PROVENANCE.md §5). FIT rows are used by the Calibration tab; OOS rows are the out-of-sample tests on TLF_Roll. Tolerance = the error that costs one unit of Solver loss.
A4: use | B4: year | C4: key | D4: statistic | E4: value | F4: tolerance | G4: quote | H4: page
A5: FIT | B5: 2024 | C5: tlf | D5: Total-loss frequency, all loss categories | E5: 0.223 | F5: 0.005 | G5: printed data label, chart "Total Loss Frequency Remains High as Vehicle Values Trend Up" (2024 = 22.3%) | H5: https://www.cccis.com/reports/crash-course-2026
A6: FIT | B6: 2024 | C6: tl7 | D6: Share of total-loss valuations on vehicles 7+ yrs | E6: 0.72 | F6: 0.01 | G6: almost 72% of valuations across all loss categories are for vehicles 7 years or older | H6: https://www.cccis.com/reports/crash-course-2024/q4
A7: FIT | B7: 2024 | C7: rp7 | D7: Share of repairable claims on vehicles 7+ yrs | E7: 0.45 | F7: 0.01 | G7: vehicles seven years or older now make up nearly 45% of all repairable claims, up from 35% in 2019 | H7: https://www.cccis.com/reports/crash-course-2024/q4
A8: FIT | B8: 2024 | C8: rp3 | D8: Share of repairable claims on vehicles ≤3 yrs (all fuel) | E8: 0.3 | F8: 0.02 | G8: Only 26.3% of repairable ICE vehicles are three years or newer (EVs 79.4% / hybrids 60.3% ≤3 yrs → all-fuel ≈30%) | H8: https://www.cccis.com/reports/crash-course-2024/q4
A9: FIT | B9: 2024 | C9: age_cl | D9: Average age of vehicles in claims (yrs) | E9: 7.6 | F9: 0.15 | G9: For claims, the average age of vehicles has increased to 7.6 years – up from 6.9 years in 2020 | H9: https://www.cccis.com/reports/crash-course-2025/q1
A10: FIT | B10: 2024 | C10: age_rp | D10: Average age of repairable vehicles (yrs) | E10: 6.8 | F10: 0.15 | G10: The average age of repairable vehicles was 6.8 years in 2024 (up from 6.1 years old in 2020) | H10: https://www.cccis.com/reports/crash-course-2025/q1
A11: FIT | B11: 2024 | C11: age_tl | D11: Average age of total-loss vehicles (yrs) | E11: 10.6 | F11: 0.15 | G11: ... and 10.6 years for total loss vehicles (up from 10.0 years old in 2020) | H11: https://www.cccis.com/reports/crash-course-2025/q1
A12: FIT | B12: 2024 | C12: p03 | D12: Total-loss rate for claims on vehicles ≤3 yrs | E12: 0.1 | F12: 0.01 | G12: For claims that are three years old or newer, 1 in 10 are flagged as a total loss by the insurer | H12: https://www.cccis.com/reports/crash-course-2026
A13: OOS | B13: 2019 | C13: rp7 | D13: Share of repairable claims on vehicles 7+ yrs | E13: 0.35 | G13: up from 35% in 2019 | H13: https://www.cccis.com/reports/crash-course-2024/q4
A14: OOS | B14: 2019 | C14: rp3 | D14: Share of repairable claims on vehicles ≤3 yrs | E14: 0.385 | G14: vehicles 3 years or newer represented 38.5% of the repairable mix in 2019 | H14: https://www.cccis.com/reports/crash-course-2025/q1
A15: OOS | B15: 2020 | C15: age_cl | D15: Average age of vehicles in claims (yrs) | E15: 6.9 | G15: up from 6.9 years in 2020 | H15: https://www.cccis.com/reports/crash-course-2025/q1
A16: OOS | B16: 2020 | C16: age_rp | D16: Average age of repairable vehicles (yrs) | E16: 6.1 | G16: up from 6.1 years old in 2020 | H16: https://www.cccis.com/reports/crash-course-2025/q1
A17: OOS | B17: 2020 | C17: age_tl | D17: Average age of total-loss vehicles (yrs) | E17: 10 | G17: up from 10.0 years old in 2020 | H17: https://www.cccis.com/reports/crash-course-2025/q1
A18: OOS | B18: 2025 | C18: tl7 | D18: Share of total-loss valuations on vehicles 7+ yrs | E18: 0.72 | G18: over 72% of total loss valuations are on vehicles 7 years or older | H18: https://www.cccis.com/reports/crash-course-2025/q4
A19: OOS | B19: 2025 | C19: rp7 | D19: Share of repairable claims on vehicles 7+ yrs | E19: 0.46 | G19: almost 46% of repairable vehicles are 7 years or older | H19: https://www.cccis.com/reports/crash-course-2025/q4
A20: OOS | B20: 2019 | C20: tlf | D20: TLF all loss categories (demographics-only model vs actual) | E20: 0.192 | G20: CCC annual 2019 = 19.2%; the gap is the non-demographic LEVEL (spread cycle, technology, filing) | H20: Data_CCC_TLF_Annual
A21: OOS | B21: 2020 | C21: tlf | D21: TLF all loss categories | E21: 0.206 | G21: CCC annual 2020 = 20.6% | H21: Data_CCC_TLF_Annual
A22: OOS | B22: 2025 | C22: tlf | D22: TLF all loss categories | E22: 0.231 | G22: CCC annual 2025 = 23.1% | H22: Data_CCC_TLF_Annual
A23: S | B23: 2024 | C23: vio | D23: Light vehicles in operation (M) | E23: 289 | G23: S&P 2025 release — NOT on disk (from memory); Experian 292.1M at Q3-2024 is on disk (Crash Course 2025/Q1) | H23: https://www.cccis.com/reports/crash-course-2025/q1
A24: S | B24: 2024 | C24: sh7 | D24: Share of fleet aged 7+ | E24: 0.66 | G24: 66% of vehicles in operation are seven years or older (S&P Mobility) | H24: https://www.cccis.com/reports/crash-course-2024/q4
A25: S | B25: 2025 | C25: viogr | D25: VIO growth 2020→Q3-2025 | E25: 0.051 | G25: Vehicles in operation reached almost 296 million as of Q3 2025 (Experian), +5.1% relative to 2020 | H25: https://www.cccis.com/reports/crash-course-2026

Sheet Survival
A1: Survival by age and calendar year — EPA schedule stretched by k(t)
A2: S(a,t) = S_EPA(a / k(t)), linearly interpolated between the table’s integer ages, zero beyond age 31·k. k(t) from Inputs row 25/26. Ages 0–45 (S is ~0 past 40).
A3: Year → | C3: =Inputs!C23 | D3: =Inputs!D23 | E3: =Inputs!E23 | F3: =Inputs!F23 | G3: =Inputs!G23 | H3: =Inputs!H23 | I3: =Inputs!I23 | J3: =Inputs!J23 | ... T3: =Inputs!T23
A4: k cars (Inputs) | C4: =Inputs!C25 | D4: =Inputs!D25 | E4: =Inputs!E25 | F4: =Inputs!F25 | G4: =Inputs!G25 | H4: =Inputs!H25 | I4: =Inputs!I25 | J4: =Inputs!J25 | ... T4: =Inputs!T25
A5: CARS: age | C5: =C3 | D5: =D3 | E5: =E3 | F5: =F3 | G5: =G3 | H5: =H3 | I5: =I3 | J5: =J3 | ... T5: =T3
A6: 0 | C6: =IF(($A6/C$4)>=31,0,INDEX(Data_EPA_Survival!$B$5:$B$36,INT(($A6/C$4))+1)+(($A6/C$4)-INT(($A6/C$4)))*(INDEX(Data_EPA_Survival!$B$5:$B$36,INT(($A6/C$4))+2)-INDEX(Data_EPA_Survival!$B$5:$B$36,INT(($A6/C$4))+1))) | D6: =IF(($A6/D$4)>=31,0,INDEX(Data_EPA_Survival!$B$5:$B$36,INT(($A6/D$4))+1)+(($A6/D$4)-INT(($A6/D$4)))*(INDEX(Data_EPA_Survival!$B$5:$B$36,INT(($A6/D$4))+2)-INDEX(Data_EPA_Survival!$B$5:$B$36,INT(($A6/D$4))+1))) | E6: =IF(($A6/E$4)>=31,0,INDEX(Data_EPA_Survival!$B$5:$B$36,INT(($A6/E$4))+1)+(($A6/E$4)-INT(($A6/E$4)))*(INDEX(Data_EPA_Survival!$B$5:$B$36,INT(($A6/E$4))+2)-INDEX(Data_EPA_Survival!$B$5:$B$36,INT(($A6/E$4))+1))) | F6: =IF(($A6/F$4)>=31,0,INDEX(Data_EPA_Survival!$B$5:$B$36,INT(($A6/F$4))+1)+(($A6/F$4)-INT(($A6/F$4)))*(INDEX(Data_EPA_Survival!$B$5:$B$36,INT(($A6/F$4))+2)-INDEX(Data_EPA_Survival!$B$5:$B$36,INT(($A6/F$4))+1))) | G6: =IF(($A6/G$4)>=31,0,INDEX(Data_EPA_Survival!$B$5:$B$36,INT(($A6/G$4))+1)+(($A6/G$4)-INT(($A6/G$4)))*(INDEX(Data_EPA_Survival!$B$5:$B$36,INT(($A6/G$4))+2)-INDEX(Data_EPA_Survival!$B$5:$B$36,INT(($A6/G$4))+1))) | H6: =IF(($A6/H$4)>=31,0,INDEX(Data_EPA_Survival!$B$5:$B$36,INT(($A6/H$4))+1)+(($A6/H$4)-INT(($A6/H$4)))*(INDEX(Data_EPA_Survival!$B$5:$B$36,INT(($A6/H$4))+2)-INDEX(Data_EPA_Survival!$B$5:$B$36,INT(($A6/H$4))+1))) | I6: =IF(($A6/I$4)>=31,0,INDEX(Data_EPA_Survival!$B$5:$B$36,INT(($A6/I$4))+1)+(($A6/I$4)-INT(($A6/I$4)))*(INDEX(Data_EPA_Survival!$B$5:$B$36,INT(($A6/I$4))+2)-INDEX(Data_EPA_Survival!$B$5:$B$36,INT(($A6/I$4))+1))) | J6: =IF(($A6/J$4)>=31,0,INDEX(Data_EPA_Survival!$B$5:$B$36,INT(($A6/J$4))+1)+(($A6/J$4)-INT(($A6/J$4)))*(INDEX(Data_EPA_Survival!$B$5:$B$36,INT(($A6/J$4))+2)-INDEX(Data_EPA_Survival!$B$5:$B$36,INT(($A6/J$4))+1))) | ... T6: =IF(($A6/T$4)>=31,0,INDEX(Data_EPA_Survival!$B$5:$B$36,INT(($A6/T$4))+1)+(($A6/T$4)-INT(($A6/T$4)))*(INDEX(Data_EPA_Survival!$B$5:$B$36,INT(($A6/T$4))+2)-INDEX(Data_EPA_Survival!$B$5:$B$36,INT(($A6/T$4))+1)))
A7: 1 | C7: =IF(($A7/C$4)>=31,0,INDEX(Data_EPA_Survival!$B$5:$B$36,INT(($A7/C$4))+1)+(($A7/C$4)-INT(($A7/C$4)))*(INDEX(Data_EPA_Survival!$B$5:$B$36,INT(($A7/C$4))+2)-INDEX(Data_EPA_Survival!$B$5:$B$36,INT(($A7/C$4))+1))) | D7: =IF(($A7/D$4)>=31,0,INDEX(Data_EPA_Survival!$B$5:$B$36,INT(($A7/D$4))+1)+(($A7/D$4)-INT(($A7/D$4)))*(INDEX(Data_EPA_Survival!$B$5:$B$36,INT(($A7/D$4))+2)-INDEX(Data_EPA_Survival!$B$5:$B$36,INT(($A7/D$4))+1))) | E7: =IF(($A7/E$4)>=31,0,INDEX(Data_EPA_Survival!$B$5:$B$36,INT(($A7/E$4))+1)+(($A7/E$4)-INT(($A7/E$4)))*(INDEX(Data_EPA_Survival!$B$5:$B$36,INT(($A7/E$4))+2)-INDEX(Data_EPA_Survival!$B$5:$B$36,INT(($A7/E$4))+1))) | F7: =IF(($A7/F$4)>=31,0,INDEX(Data_EPA_Survival!$B$5:$B$36,INT(($A7/F$4))+1)+(($A7/F$4)-INT(($A7/F$4)))*(INDEX(Data_EPA_Survival!$B$5:$B$36,INT(($A7/F$4))+2)-INDEX(Data_EPA_Survival!$B$5:$B$36,INT(($A7/F$4))+1))) | G7: =IF(($A7/G$4)>=31,0,INDEX(Data_EPA_Survival!$B$5:$B$36,INT(($A7/G$4))+1)+(($A7/G$4)-INT(($A7/G$4)))*(INDEX(Data_EPA_Survival!$B$5:$B$36,INT(($A7/G$4))+2)-INDEX(Data_EPA_Survival!$B$5:$B$36,INT(($A7/G$4))+1))) | H7: =IF(($A7/H$4)>=31,0,INDEX(Data_EPA_Survival!$B$5:$B$36,INT(($A7/H$4))+1)+(($A7/H$4)-INT(($A7/H$4)))*(INDEX(Data_EPA_Survival!$B$5:$B$36,INT(($A7/H$4))+2)-INDEX(Data_EPA_Survival!$B$5:$B$36,INT(($A7/H$4))+1))) | I7: =IF(($A7/I$4)>=31,0,INDEX(Data_EPA_Survival!$B$5:$B$36,INT(($A7/I$4))+1)+(($A7/I$4)-INT(($A7/I$4)))*(INDEX(Data_EPA_Survival!$B$5:$B$36,INT(($A7/I$4))+2)-INDEX(Data_EPA_Survival!$B$5:$B$36,INT(($A7/I$4))+1))) | J7: =IF(($A7/J$4)>=31,0,INDEX(Data_EPA_Survival!$B$5:$B$36,INT(($A7/J$4))+1)+(($A7/J$4)-INT(($A7/J$4)))*(INDEX(Data_EPA_Survival!$B$5:$B$36,INT(($A7/J$4))+2)-INDEX(Data_EPA_Survival!$B$5:$B$36,INT(($A7/J$4))+1))) | ... T7: =IF(($A7/T$4)>=31,0,INDEX(Data_EPA_Survival!$B$5:$B$36,INT(($A7/T$4))+1)+(($A7/T$4)-INT(($A7/T$4)))*(INDEX(Data_EPA_Survival!$B$5:$B$36,INT(($A7/T$4))+2)-INDEX(Data_EPA_Survival!$B$5:$B$36,INT(($A7/T$4))+1)))
A8: 2 | C8: =IF(($A8/C$4)>=31,0,INDEX(Data_EPA_Survival!$B$5:$B$36,INT(($A8/C$4))+1)+(($A8/C$4)-INT(($A8/C$4)))*(INDEX(Data_EPA_Survival!$B$5:$B$36,INT(($A8/C$4))+2)-INDEX(Data_EPA_Survival!$B$5:$B$36,INT(($A8/C$4))+1))) | D8: =IF(($A8/D$4)>=31,0,INDEX(Data_EPA_Survival!$B$5:$B$36,INT(($A8/D$4))+1)+(($A8/D$4)-INT(($A8/D$4)))*(INDEX(Data_EPA_Survival!$B$5:$B$36,INT(($A8/D$4))+2)-INDEX(Data_EPA_Survival!$B$5:$B$36,INT(($A8/D$4))+1))) | E8: =IF(($A8/E$4)>=31,0,INDEX(Data_EPA_Survival!$B$5:$B$36,INT(($A8/E$4))+1)+(($A8/E$4)-INT(($A8/E$4)))*(INDEX(Data_EPA_Survival!$B$5:$B$36,INT(($A8/E$4))+2)-INDEX(Data_EPA_Survival!$B$5:$B$36,INT(($A8/E$4))+1))) | F8: =IF(($A8/F$4)>=31,0,INDEX(Data_EPA_Survival!$B$5:$B$36,INT(($A8/F$4))+1)+(($A8/F$4)-INT(($A8/F$4)))*(INDEX(Data_EPA_Survival!$B$5:$B$36,INT(($A8/F$4))+2)-INDEX(Data_EPA_Survival!$B$5:$B$36,INT(($A8/F$4))+1))) | G8: =IF(($A8/G$4)>=31,0,INDEX(Data_EPA_Survival!$B$5:$B$36,INT(($A8/G$4))+1)+(($A8/G$4)-INT(($A8/G$4)))*(INDEX(Data_EPA_Survival!$B$5:$B$36,INT(($A8/G$4))+2)-INDEX(Data_EPA_Survival!$B$5:$B$36,INT(($A8/G$4))+1))) | H8: =IF(($A8/H$4)>=31,0,INDEX(Data_EPA_Survival!$B$5:$B$36,INT(($A8/H$4))+1)+(($A8/H$4)-INT(($A8/H$4)))*(INDEX(Data_EPA_Survival!$B$5:$B$36,INT(($A8/H$4))+2)-INDEX(Data_EPA_Survival!$B$5:$B$36,INT(($A8/H$4))+1))) | I8: =IF(($A8/I$4)>=31,0,INDEX(Data_EPA_Survival!$B$5:$B$36,INT(($A8/I$4))+1)+(($A8/I$4)-INT(($A8/I$4)))*(INDEX(Data_EPA_Survival!$B$5:$B$36,INT(($A8/I$4))+2)-INDEX(Data_EPA_Survival!$B$5:$B$36,INT(($A8/I$4))+1))) | J8: =IF(($A8/J$4)>=31,0,INDEX(Data_EPA_Survival!$B$5:$B$36,INT(($A8/J$4))+1)+(($A8/J$4)-INT(($A8/J$4)))*(INDEX(Data_EPA_Survival!$B$5:$B$36,INT(($A8/J$4))+2)-INDEX(Data_EPA_Survival!$B$5:$B$36,INT(($A8/J$4))+1))) | ... T8: =IF(($A8/T$4)>=31,0,INDEX(Data_EPA_Survival!$B$5:$B$36,INT(($A8/T$4))+1)+(($A8/T$4)-INT(($A8/T$4)))*(INDEX(Data_EPA_Survival!$B$5:$B$36,INT(($A8/T$4))+2)-INDEX(Data_EPA_Survival!$B$5:$B$36,INT(($A8/T$4))+1)))
A9: 3 | C9: =IF(($A9/C$4)>=31,0,INDEX(Data_EPA_Survival!$B$5:$B$36,INT(($A9/C$4))+1)+(($A9/C$4)-INT(($A9/C$4)))*(INDEX(Data_EPA_Survival!$B$5:$B$36,INT(($A9/C$4))+2)-INDEX(Data_EPA_Survival!$B$5:$B$36,INT(($A9/C$4))+1))) | D9: =IF(($A9/D$4)>=31,0,INDEX(Data_EPA_Survival!$B$5:$B$36,INT(($A9/D$4))+1)+(($A9/D$4)-INT(($A9/D$4)))*(INDEX(Data_EPA_Survival!$B$5:$B$36,INT(($A9/D$4))+2)-INDEX(Data_EPA_Survival!$B$5:$B$36,INT(($A9/D$4))+1))) | E9: =IF(($A9/E$4)>=31,0,INDEX(Data_EPA_Survival!$B$5:$B$36,INT(($A9/E$4))+1)+(($A9/E$4)-INT(($A9/E$4)))*(INDEX(Data_EPA_Survival!$B$5:$B$36,INT(($A9/E$4))+2)-INDEX(Data_EPA_Survival!$B$5:$B$36,INT(($A9/E$4))+1))) | F9: =IF(($A9/F$4)>=31,0,INDEX(Data_EPA_Survival!$B$5:$B$36,INT(($A9/F$4))+1)+(($A9/F$4)-INT(($A9/F$4)))*(INDEX(Data_EPA_Survival!$B$5:$B$36,INT(($A9/F$4))+2)-INDEX(Data_EPA_Survival!$B$5:$B$36,INT(($A9/F$4))+1))) | G9: =IF(($A9/G$4)>=31,0,INDEX(Data_EPA_Survival!$B$5:$B$36,INT(($A9/G$4))+1)+(($A9/G$4)-INT(($A9/G$4)))*(INDEX(Data_EPA_Survival!$B$5:$B$36,INT(($A9/G$4))+2)-INDEX(Data_EPA_Survival!$B$5:$B$36,INT(($A9/G$4))+1))) | H9: =IF(($A9/H$4)>=31,0,INDEX(Data_EPA_Survival!$B$5:$B$36,INT(($A9/H$4))+1)+(($A9/H$4)-INT(($A9/H$4)))*(INDEX(Data_EPA_Survival!$B$5:$B$36,INT(($A9/H$4))+2)-INDEX(Data_EPA_Survival!$B$5:$B$36,INT(($A9/H$4))+1))) | I9: =IF(($A9/I$4)>=31,0,INDEX(Data_EPA_Survival!$B$5:$B$36,INT(($A9/I$4))+1)+(($A9/I$4)-INT(($A9/I$4)))*(INDEX(Data_EPA_Survival!$B$5:$B$36,INT(($A9/I$4))+2)-INDEX(Data_EPA_Survival!$B$5:$B$36,INT(($A9/I$4))+1))) | J9: =IF(($A9/J$4)>=31,0,INDEX(Data_EPA_Survival!$B$5:$B$36,INT(($A9/J$4))+1)+(($A9/J$4)-INT(($A9/J$4)))*(INDEX(Data_EPA_Survival!$B$5:$B$36,INT(($A9/J$4))+2)-INDEX(Data_EPA_Survival!$B$5:$B$36,INT(($A9/J$4))+1))) | ... T9: =IF(($A9/T$4)>=31,0,INDEX(Data_EPA_Survival!$B$5:$B$36,INT(($A9/T$4))+1)+(($A9/T$4)-INT(($A9/T$4)))*(INDEX(Data_EPA_Survival!$B$5:$B$36,INT(($A9/T$4))+2)-INDEX(Data_EPA_Survival!$B$5:$B$36,INT(($A9/T$4))+1)))
A10: 4 | C10: =IF(($A10/C$4)>=31,0,INDEX(Data_EPA_Survival!$B$5:$B$36,INT(($A10/C$4))+1)+(($A10/C$4)-INT(($A10/C$4)))*(INDEX(Data_EPA_Survival!$B$5:$B$36,INT(($A10/C$4))+2)-INDEX(Data_EPA_Survival!$B$5:$B$36,INT(($A10/C$4))+1))) | D10: =IF(($A10/D$4)>=31,0,INDEX(Data_EPA_Survival!$B$5:$B$36,INT(($A10/D$4))+1)+(($A10/D$4)-INT(($A10/D$4)))*(INDEX(Data_EPA_Survival!$B$5:$B$36,INT(($A10/D$4))+2)-INDEX(Data_EPA_Survival!$B$5:$B$36,INT(($A10/D$4))+1))) | E10: =IF(($A10/E$4)>=31,0,INDEX(Data_EPA_Survival!$B$5:$B$36,INT(($A10/E$4))+1)+(($A10/E$4)-INT(($A10/E$4)))*(INDEX(Data_EPA_Survival!$B$5:$B$36,INT(($A10/E$4))+2)-INDEX(Data_EPA_Survival!$B$5:$B$36,INT(($A10/E$4))+1))) | F10: =IF(($A10/F$4)>=31,0,INDEX(Data_EPA_Survival!$B$5:$B$36,INT(($A10/F$4))+1)+(($A10/F$4)-INT(($A10/F$4)))*(INDEX(Data_EPA_Survival!$B$5:$B$36,INT(($A10/F$4))+2)-INDEX(Data_EPA_Survival!$B$5:$B$36,INT(($A10/F$4))+1))) | G10: =IF(($A10/G$4)>=31,0,INDEX(Data_EPA_Survival!$B$5:$B$36,INT(($A10/G$4))+1)+(($A10/G$4)-INT(($A10/G$4)))*(INDEX(Data_EPA_Survival!$B$5:$B$36,INT(($A10/G$4))+2)-INDEX(Data_EPA_Survival!$B$5:$B$36,INT(($A10/G$4))+1))) | H10: =IF(($A10/H$4)>=31,0,INDEX(Data_EPA_Survival!$B$5:$B$36,INT(($A10/H$4))+1)+(($A10/H$4)-INT(($A10/H$4)))*(INDEX(Data_EPA_Survival!$B$5:$B$36,INT(($A10/H$4))+2)-INDEX(Data_EPA_Survival!$B$5:$B$36,INT(($A10/H$4))+1))) | I10: =IF(($A10/I$4)>=31,0,INDEX(Data_EPA_Survival!$B$5:$B$36,INT(($A10/I$4))+1)+(($A10/I$4)-INT(($A10/I$4)))*(INDEX(Data_EPA_Survival!$B$5:$B$36,INT(($A10/I$4))+2)-INDEX(Data_EPA_Survival!$B$5:$B$36,INT(($A10/I$4))+1))) | J10: =IF(($A10/J$4)>=31,0,INDEX(Data_EPA_Survival!$B$5:$B$36,INT(($A10/J$4))+1)+(($A10/J$4)-INT(($A10/J$4)))*(INDEX(Data_EPA_Survival!$B$5:$B$36,INT(($A10/J$4))+2)-INDEX(Data_EPA_Survival!$B$5:$B$36,INT(($A10/J$4))+1))) | ... T10: =IF(($A10/T$4)>=31,0,INDEX(Data_EPA_Survival!$B$5:$B$36,INT(($A10/T$4))+1)+(($A10/T$4)-INT(($A10/T$4)))*(INDEX(Data_EPA_Survival!$B$5:$B$36,INT(($A10/T$4))+2)-INDEX(Data_EPA_Survival!$B$5:$B$36,INT(($A10/T$4))+1)))
A11: 5 | C11: =IF(($A11/C$4)>=31,0,INDEX(Data_EPA_Survival!$B$5:$B$36,INT(($A11/C$4))+1)+(($A11/C$4)-INT(($A11/C$4)))*(INDEX(Data_EPA_Survival!$B$5:$B$36,INT(($A11/C$4))+2)-INDEX(Data_EPA_Survival!$B$5:$B$36,INT(($A11/C$4))+1))) | D11: =IF(($A11/D$4)>=31,0,INDEX(Data_EPA_Survival!$B$5:$B$36,INT(($A11/D$4))+1)+(($A11/D$4)-INT(($A11/D$4)))*(INDEX(Data_EPA_Survival!$B$5:$B$36,INT(($A11/D$4))+2)-INDEX(Data_EPA_Survival!$B$5:$B$36,INT(($A11/D$4))+1))) | E11: =IF(($A11/E$4)>=31,0,INDEX(Data_EPA_Survival!$B$5:$B$36,INT(($A11/E$4))+1)+(($A11/E$4)-INT(($A11/E$4)))*(INDEX(Data_EPA_Survival!$B$5:$B$36,INT(($A11/E$4))+2)-INDEX(Data_EPA_Survival!$B$5:$B$36,INT(($A11/E$4))+1))) | F11: =IF(($A11/F$4)>=31,0,INDEX(Data_EPA_Survival!$B$5:$B$36,INT(($A11/F$4))+1)+(($A11/F$4)-INT(($A11/F$4)))*(INDEX(Data_EPA_Survival!$B$5:$B$36,INT(($A11/F$4))+2)-INDEX(Data_EPA_Survival!$B$5:$B$36,INT(($A11/F$4))+1))) | G11: =IF(($A11/G$4)>=31,0,INDEX(Data_EPA_Survival!$B$5:$B$36,INT(($A11/G$4))+1)+(($A11/G$4)-INT(($A11/G$4)))*(INDEX(Data_EPA_Survival!$B$5:$B$36,INT(($A11/G$4))+2)-INDEX(Data_EPA_Survival!$B$5:$B$36,INT(($A11/G$4))+1))) | H11: =IF(($A11/H$4)>=31,0,INDEX(Data_EPA_Survival!$B$5:$B$36,INT(($A11/H$4))+1)+(($A11/H$4)-INT(($A11/H$4)))*(INDEX(Data_EPA_Survival!$B$5:$B$36,INT(($A11/H$4))+2)-INDEX(Data_EPA_Survival!$B$5:$B$36,INT(($A11/H$4))+1))) | I11: =IF(($A11/I$4)>=31,0,INDEX(Data_EPA_Survival!$B$5:$B$36,INT(($A11/I$4))+1)+(($A11/I$4)-INT(($A11/I$4)))*(INDEX(Data_EPA_Survival!$B$5:$B$36,INT(($A11/I$4))+2)-INDEX(Data_EPA_Survival!$B$5:$B$36,INT(($A11/I$4))+1))) | J11: =IF(($A11/J$4)>=31,0,INDEX(Data_EPA_Survival!$B$5:$B$36,INT(($A11/J$4))+1)+(($A11/J$4)-INT(($A11/J$4)))*(INDEX(Data_EPA_Survival!$B$5:$B$36,INT(($A11/J$4))+2)-INDEX(Data_EPA_Survival!$B$5:$B$36,INT(($A11/J$4))+1))) | ... T11: =IF(($A11/T$4)>=31,0,INDEX(Data_EPA_Survival!$B$5:$B$36,INT(($A11/T$4))+1)+(($A11/T$4)-INT(($A11/T$4)))*(INDEX(Data_EPA_Survival!$B$5:$B$36,INT(($A11/T$4))+2)-INDEX(Data_EPA_Survival!$B$5:$B$36,INT(($A11/T$4))+1)))
A12: 6 | C12: =IF(($A12/C$4)>=31,0,INDEX(Data_EPA_Survival!$B$5:$B$36,INT(($A12/C$4))+1)+(($A12/C$4)-INT(($A12/C$4)))*(INDEX(Data_EPA_Survival!$B$5:$B$36,INT(($A12/C$4))+2)-INDEX(Data_EPA_Survival!$B$5:$B$36,INT(($A12/C$4))+1))) | D12: =IF(($A12/D$4)>=31,0,INDEX(Data_EPA_Survival!$B$5:$B$36,INT(($A12/D$4))+1)+(($A12/D$4)-INT(($A12/D$4)))*(INDEX(Data_EPA_Survival!$B$5:$B$36,INT(($A12/D$4))+2)-INDEX(Data_EPA_Survival!$B$5:$B$36,INT(($A12/D$4))+1))) | E12: =IF(($A12/E$4)>=31,0,INDEX(Data_EPA_Survival!$B$5:$B$36,INT(($A12/E$4))+1)+(($A12/E$4)-INT(($A12/E$4)))*(INDEX(Data_EPA_Survival!$B$5:$B$36,INT(($A12/E$4))+2)-INDEX(Data_EPA_Survival!$B$5:$B$36,INT(($A12/E$4))+1))) | F12: =IF(($A12/F$4)>=31,0,INDEX(Data_EPA_Survival!$B$5:$B$36,INT(($A12/F$4))+1)+(($A12/F$4)-INT(($A12/F$4)))*(INDEX(Data_EPA_Survival!$B$5:$B$36,INT(($A12/F$4))+2)-INDEX(Data_EPA_Survival!$B$5:$B$36,INT(($A12/F$4))+1))) | G12: =IF(($A12/G$4)>=31,0,INDEX(Data_EPA_Survival!$B$5:$B$36,INT(($A12/G$4))+1)+(($A12/G$4)-INT(($A12/G$4)))*(INDEX(Data_EPA_Survival!$B$5:$B$36,INT(($A12/G$4))+2)-INDEX(Data_EPA_Survival!$B$5:$B$36,INT(($A12/G$4))+1))) | H12: =IF(($A12/H$4)>=31,0,INDEX(Data_EPA_Survival!$B$5:$B$36,INT(($A12/H$4))+1)+(($A12/H$4)-INT(($A12/H$4)))*(INDEX(Data_EPA_Survival!$B$5:$B$36,INT(($A12/H$4))+2)-INDEX(Data_EPA_Survival!$B$5:$B$36,INT(($A12/H$4))+1))) | I12: =IF(($A12/I$4)>=31,0,INDEX(Data_EPA_Survival!$B$5:$B$36,INT(($A12/I$4))+1)+(($A12/I$4)-INT(($A12/I$4)))*(INDEX(Data_EPA_Survival!$B$5:$B$36,INT(($A12/I$4))+2)-INDEX(Data_EPA_Survival!$B$5:$B$36,INT(($A12/I$4))+1))) | J12: =IF(($A12/J$4)>=31,0,INDEX(Data_EPA_Survival!$B$5:$B$36,INT(($A12/J$4))+1)+(($A12/J$4)-INT(($A12/J$4)))*(INDEX(Data_EPA_Survival!$B$5:$B$36,INT(($A12/J$4))+2)-INDEX(Data_EPA_Survival!$B$5:$B$36,INT(($A12/J$4))+1))) | ... T12: =IF(($A12/T$4)>=31,0,INDEX(Data_EPA_Survival!$B$5:$B$36,INT(($A12/T$4))+1)+(($A12/T$4)-INT(($A12/T$4)))*(INDEX(Data_EPA_Survival!$B$5:$B$36,INT(($A12/T$4))+2)-INDEX(Data_EPA_Survival!$B$5:$B$36,INT(($A12/T$4))+1)))
A13: 7 | C13: =IF(($A13/C$4)>=31,0,INDEX(Data_EPA_Survival!$B$5:$B$36,INT(($A13/C$4))+1)+(($A13/C$4)-INT(($A13/C$4)))*(INDEX(Data_EPA_Survival!$B$5:$B$36,INT(($A13/C$4))+2)-INDEX(Data_EPA_Survival!$B$5:$B$36,INT(($A13/C$4))+1))) | D13: =IF(($A13/D$4)>=31,0,INDEX(Data_EPA_Survival!$B$5:$B$36,INT(($A13/D$4))+1)+(($A13/D$4)-INT(($A13/D$4)))*(INDEX(Data_EPA_Survival!$B$5:$B$36,INT(($A13/D$4))+2)-INDEX(Data_EPA_Survival!$B$5:$B$36,INT(($A13/D$4))+1))) | E13: =IF(($A13/E$4)>=31,0,INDEX(Data_EPA_Survival!$B$5:$B$36,INT(($A13/E$4))+1)+(($A13/E$4)-INT(($A13/E$4)))*(INDEX(Data_EPA_Survival!$B$5:$B$36,INT(($A13/E$4))+2)-INDEX(Data_EPA_Survival!$B$5:$B$36,INT(($A13/E$4))+1))) | F13: =IF(($A13/F$4)>=31,0,INDEX(Data_EPA_Survival!$B$5:$B$36,INT(($A13/F$4))+1)+(($A13/F$4)-INT(($A13/F$4)))*(INDEX(Data_EPA_Survival!$B$5:$B$36,INT(($A13/F$4))+2)-INDEX(Data_EPA_Survival!$B$5:$B$36,INT(($A13/F$4))+1))) | G13: =IF(($A13/G$4)>=31,0,INDEX(Data_EPA_Survival!$B$5:$B$36,INT(($A13/G$4))+1)+(($A13/G$4)-INT(($A13/G$4)))*(INDEX(Data_EPA_Survival!$B$5:$B$36,INT(($A13/G$4))+2)-INDEX(Data_EPA_Survival!$B$5:$B$36,INT(($A13/G$4))+1))) | H13: =IF(($A13/H$4)>=31,0,INDEX(Data_EPA_Survival!$B$5:$B$36,INT(($A13/H$4))+1)+(($A13/H$4)-INT(($A13/H$4)))*(INDEX(Data_EPA_Survival!$B$5:$B$36,INT(($A13/H$4))+2)-INDEX(Data_EPA_Survival!$B$5:$B$36,INT(($A13/H$4))+1))) | I13: =IF(($A13/I$4)>=31,0,INDEX(Data_EPA_Survival!$B$5:$B$36,INT(($A13/I$4))+1)+(($A13/I$4)-INT(($A13/I$4)))*(INDEX(Data_EPA_Survival!$B$5:$B$36,INT(($A13/I$4))+2)-INDEX(Data_EPA_Survival!$B$5:$B$36,INT(($A13/I$4))+1))) | J13: =IF(($A13/J$4)>=31,0,INDEX(Data_EPA_Survival!$B$5:$B$36,INT(($A13/J$4))+1)+(($A13/J$4)-INT(($A13/J$4)))*(INDEX(Data_EPA_Survival!$B$5:$B$36,INT(($A13/J$4))+2)-INDEX(Data_EPA_Survival!$B$5:$B$36,INT(($A13/J$4))+1))) | ... T13: =IF(($A13/T$4)>=31,0,INDEX(Data_EPA_Survival!$B$5:$B$36,INT(($A13/T$4))+1)+(($A13/T$4)-INT(($A13/T$4)))*(INDEX(Data_EPA_Survival!$B$5:$B$36,INT(($A13/T$4))+2)-INDEX(Data_EPA_Survival!$B$5:$B$36,INT(($A13/T$4))+1)))
A14: 8 | C14: =IF(($A14/C$4)>=31,0,INDEX(Data_EPA_Survival!$B$5:$B$36,INT(($A14/C$4))+1)+(($A14/C$4)-INT(($A14/C$4)))*(INDEX(Data_EPA_Survival!$B$5:$B$36,INT(($A14/C$4))+2)-INDEX(Data_EPA_Survival!$B$5:$B$36,INT(($A14/C$4))+1))) | D14: =IF(($A14/D$4)>=31,0,INDEX(Data_EPA_Survival!$B$5:$B$36,INT(($A14/D$4))+1)+(($A14/D$4)-INT(($A14/D$4)))*(INDEX(Data_EPA_Survival!$B$5:$B$36,INT(($A14/D$4))+2)-INDEX(Data_EPA_Survival!$B$5:$B$36,INT(($A14/D$4))+1))) | E14: =IF(($A14/E$4)>=31,0,INDEX(Data_EPA_Survival!$B$5:$B$36,INT(($A14/E$4))+1)+(($A14/E$4)-INT(($A14/E$4)))*(INDEX(Data_EPA_Survival!$B$5:$B$36,INT(($A14/E$4))+2)-INDEX(Data_EPA_Survival!$B$5:$B$36,INT(($A14/E$4))+1))) | F14: =IF(($A14/F$4)>=31,0,INDEX(Data_EPA_Survival!$B$5:$B$36,INT(($A14/F$4))+1)+(($A14/F$4)-INT(($A14/F$4)))*(INDEX(Data_EPA_Survival!$B$5:$B$36,INT(($A14/F$4))+2)-INDEX(Data_EPA_Survival!$B$5:$B$36,INT(($A14/F$4))+1))) | G14: =IF(($A14/G$4)>=31,0,INDEX(Data_EPA_Survival!$B$5:$B$36,INT(($A14/G$4))+1)+(($A14/G$4)-INT(($A14/G$4)))*(INDEX(Data_EPA_Survival!$B$5:$B$36,INT(($A14/G$4))+2)-INDEX(Data_EPA_Survival!$B$5:$B$36,INT(($A14/G$4))+1))) | H14: =IF(($A14/H$4)>=31,0,INDEX(Data_EPA_Survival!$B$5:$B$36,INT(($A14/H$4))+1)+(($A14/H$4)-INT(($A14/H$4)))*(INDEX(Data_EPA_Survival!$B$5:$B$36,INT(($A14/H$4))+2)-INDEX(Data_EPA_Survival!$B$5:$B$36,INT(($A14/H$4))+1))) | I14: =IF(($A14/I$4)>=31,0,INDEX(Data_EPA_Survival!$B$5:$B$36,INT(($A14/I$4))+1)+(($A14/I$4)-INT(($A14/I$4)))*(INDEX(Data_EPA_Survival!$B$5:$B$36,INT(($A14/I$4))+2)-INDEX(Data_EPA_Survival!$B$5:$B$36,INT(($A14/I$4))+1))) | J14: =IF(($A14/J$4)>=31,0,INDEX(Data_EPA_Survival!$B$5:$B$36,INT(($A14/J$4))+1)+(($A14/J$4)-INT(($A14/J$4)))*(INDEX(Data_EPA_Survival!$B$5:$B$36,INT(($A14/J$4))+2)-INDEX(Data_EPA_Survival!$B$5:$B$36,INT(($A14/J$4))+1))) | ... T14: =IF(($A14/T$4)>=31,0,INDEX(Data_EPA_Survival!$B$5:$B$36,INT(($A14/T$4))+1)+(($A14/T$4)-INT(($A14/T$4)))*(INDEX(Data_EPA_Survival!$B$5:$B$36,INT(($A14/T$4))+2)-INDEX(Data_EPA_Survival!$B$5:$B$36,INT(($A14/T$4))+1)))
A15: 9 | C15: =IF(($A15/C$4)>=31,0,INDEX(Data_EPA_Survival!$B$5:$B$36,INT(($A15/C$4))+1)+(($A15/C$4)-INT(($A15/C$4)))*(INDEX(Data_EPA_Survival!$B$5:$B$36,INT(($A15/C$4))+2)-INDEX(Data_EPA_Survival!$B$5:$B$36,INT(($A15/C$4))+1))) | D15: =IF(($A15/D$4)>=31,0,INDEX(Data_EPA_Survival!$B$5:$B$36,INT(($A15/D$4))+1)+(($A15/D$4)-INT(($A15/D$4)))*(INDEX(Data_EPA_Survival!$B$5:$B$36,INT(($A15/D$4))+2)-INDEX(Data_EPA_Survival!$B$5:$B$36,INT(($A15/D$4))+1))) | E15: =IF(($A15/E$4)>=31,0,INDEX(Data_EPA_Survival!$B$5:$B$36,INT(($A15/E$4))+1)+(($A15/E$4)-INT(($A15/E$4)))*(INDEX(Data_EPA_Survival!$B$5:$B$36,INT(($A15/E$4))+2)-INDEX(Data_EPA_Survival!$B$5:$B$36,INT(($A15/E$4))+1))) | F15: =IF(($A15/F$4)>=31,0,INDEX(Data_EPA_Survival!$B$5:$B$36,INT(($A15/F$4))+1)+(($A15/F$4)-INT(($A15/F$4)))*(INDEX(Data_EPA_Survival!$B$5:$B$36,INT(($A15/F$4))+2)-INDEX(Data_EPA_Survival!$B$5:$B$36,INT(($A15/F$4))+1))) | G15: =IF(($A15/G$4)>=31,0,INDEX(Data_EPA_Survival!$B$5:$B$36,INT(($A15/G$4))+1)+(($A15/G$4)-INT(($A15/G$4)))*(INDEX(Data_EPA_Survival!$B$5:$B$36,INT(($A15/G$4))+2)-INDEX(Data_EPA_Survival!$B$5:$B$36,INT(($A15/G$4))+1))) | H15: =IF(($A15/H$4)>=31,0,INDEX(Data_EPA_Survival!$B$5:$B$36,INT(($A15/H$4))+1)+(($A15/H$4)-INT(($A15/H$4)))*(INDEX(Data_EPA_Survival!$B$5:$B$36,INT(($A15/H$4))+2)-INDEX(Data_EPA_Survival!$B$5:$B$36,INT(($A15/H$4))+1))) | I15: =IF(($A15/I$4)>=31,0,INDEX(Data_EPA_Survival!$B$5:$B$36,INT(($A15/I$4))+1)+(($A15/I$4)-INT(($A15/I$4)))*(INDEX(Data_EPA_Survival!$B$5:$B$36,INT(($A15/I$4))+2)-INDEX(Data_EPA_Survival!$B$5:$B$36,INT(($A15/I$4))+1))) | J15: =IF(($A15/J$4)>=31,0,INDEX(Data_EPA_Survival!$B$5:$B$36,INT(($A15/J$4))+1)+(($A15/J$4)-INT(($A15/J$4)))*(INDEX(Data_EPA_Survival!$B$5:$B$36,INT(($A15/J$4))+2)-INDEX(Data_EPA_Survival!$B$5:$B$36,INT(($A15/J$4))+1))) | ... T15: =IF(($A15/T$4)>=31,0,INDEX(Data_EPA_Survival!$B$5:$B$36,INT(($A15/T$4))+1)+(($A15/T$4)-INT(($A15/T$4)))*(INDEX(Data_EPA_Survival!$B$5:$B$36,INT(($A15/T$4))+2)-INDEX(Data_EPA_Survival!$B$5:$B$36,INT(($A15/T$4))+1)))
A16: 10 | C16: =IF(($A16/C$4)>=31,0,INDEX(Data_EPA_Survival!$B$5:$B$36,INT(($A16/C$4))+1)+(($A16/C$4)-INT(($A16/C$4)))*(INDEX(Data_EPA_Survival!$B$5:$B$36,INT(($A16/C$4))+2)-INDEX(Data_EPA_Survival!$B$5:$B$36,INT(($A16/C$4))+1))) | D16: =IF(($A16/D$4)>=31,0,INDEX(Data_EPA_Survival!$B$5:$B$36,INT(($A16/D$4))+1)+(($A16/D$4)-INT(($A16/D$4)))*(INDEX(Data_EPA_Survival!$B$5:$B$36,INT(($A16/D$4))+2)-INDEX(Data_EPA_Survival!$B$5:$B$36,INT(($A16/D$4))+1))) | E16: =IF(($A16/E$4)>=31,0,INDEX(Data_EPA_Survival!$B$5:$B$36,INT(($A16/E$4))+1)+(($A16/E$4)-INT(($A16/E$4)))*(INDEX(Data_EPA_Survival!$B$5:$B$36,INT(($A16/E$4))+2)-INDEX(Data_EPA_Survival!$B$5:$B$36,INT(($A16/E$4))+1))) | F16: =IF(($A16/F$4)>=31,0,INDEX(Data_EPA_Survival!$B$5:$B$36,INT(($A16/F$4))+1)+(($A16/F$4)-INT(($A16/F$4)))*(INDEX(Data_EPA_Survival!$B$5:$B$36,INT(($A16/F$4))+2)-INDEX(Data_EPA_Survival!$B$5:$B$36,INT(($A16/F$4))+1))) | G16: =IF(($A16/G$4)>=31,0,INDEX(Data_EPA_Survival!$B$5:$B$36,INT(($A16/G$4))+1)+(($A16/G$4)-INT(($A16/G$4)))*(INDEX(Data_EPA_Survival!$B$5:$B$36,INT(($A16/G$4))+2)-INDEX(Data_EPA_Survival!$B$5:$B$36,INT(($A16/G$4))+1))) | H16: =IF(($A16/H$4)>=31,0,INDEX(Data_EPA_Survival!$B$5:$B$36,INT(($A16/H$4))+1)+(($A16/H$4)-INT(($A16/H$4)))*(INDEX(Data_EPA_Survival!$B$5:$B$36,INT(($A16/H$4))+2)-INDEX(Data_EPA_Survival!$B$5:$B$36,INT(($A16/H$4))+1))) | I16: =IF(($A16/I$4)>=31,0,INDEX(Data_EPA_Survival!$B$5:$B$36,INT(($A16/I$4))+1)+(($A16/I$4)-INT(($A16/I$4)))*(INDEX(Data_EPA_Survival!$B$5:$B$36,INT(($A16/I$4))+2)-INDEX(Data_EPA_Survival!$B$5:$B$36,INT(($A16/I$4))+1))) | J16: =IF(($A16/J$4)>=31,0,INDEX(Data_EPA_Survival!$B$5:$B$36,INT(($A16/J$4))+1)+(($A16/J$4)-INT(($A16/J$4)))*(INDEX(Data_EPA_Survival!$B$5:$B$36,INT(($A16/J$4))+2)-INDEX(Data_EPA_Survival!$B$5:$B$36,INT(($A16/J$4))+1))) | ... T16: =IF(($A16/T$4)>=31,0,INDEX(Data_EPA_Survival!$B$5:$B$36,INT(($A16/T$4))+1)+(($A16/T$4)-INT(($A16/T$4)))*(INDEX(Data_EPA_Survival!$B$5:$B$36,INT(($A16/T$4))+2)-INDEX(Data_EPA_Survival!$B$5:$B$36,INT(($A16/T$4))+1)))
A17: 11 | C17: =IF(($A17/C$4)>=31,0,INDEX(Data_EPA_Survival!$B$5:$B$36,INT(($A17/C$4))+1)+(($A17/C$4)-INT(($A17/C$4)))*(INDEX(Data_EPA_Survival!$B$5:$B$36,INT(($A17/C$4))+2)-INDEX(Data_EPA_Survival!$B$5:$B$36,INT(($A17/C$4))+1))) | D17: =IF(($A17/D$4)>=31,0,INDEX(Data_EPA_Survival!$B$5:$B$36,INT(($A17/D$4))+1)+(($A17/D$4)-INT(($A17/D$4)))*(INDEX(Data_EPA_Survival!$B$5:$B$36,INT(($A17/D$4))+2)-INDEX(Data_EPA_Survival!$B$5:$B$36,INT(($A17/D$4))+1))) | E17: =IF(($A17/E$4)>=31,0,INDEX(Data_EPA_Survival!$B$5:$B$36,INT(($A17/E$4))+1)+(($A17/E$4)-INT(($A17/E$4)))*(INDEX(Data_EPA_Survival!$B$5:$B$36,INT(($A17/E$4))+2)-INDEX(Data_EPA_Survival!$B$5:$B$36,INT(($A17/E$4))+1))) | F17: =IF(($A17/F$4)>=31,0,INDEX(Data_EPA_Survival!$B$5:$B$36,INT(($A17/F$4))+1)+(($A17/F$4)-INT(($A17/F$4)))*(INDEX(Data_EPA_Survival!$B$5:$B$36,INT(($A17/F$4))+2)-INDEX(Data_EPA_Survival!$B$5:$B$36,INT(($A17/F$4))+1))) | G17: =IF(($A17/G$4)>=31,0,INDEX(Data_EPA_Survival!$B$5:$B$36,INT(($A17/G$4))+1)+(($A17/G$4)-INT(($A17/G$4)))*(INDEX(Data_EPA_Survival!$B$5:$B$36,INT(($A17/G$4))+2)-INDEX(Data_EPA_Survival!$B$5:$B$36,INT(($A17/G$4))+1))) | H17: =IF(($A17/H$4)>=31,0,INDEX(Data_EPA_Survival!$B$5:$B$36,INT(($A17/H$4))+1)+(($A17/H$4)-INT(($A17/H$4)))*(INDEX(Data_EPA_Survival!$B$5:$B$36,INT(($A17/H$4))+2)-INDEX(Data_EPA_Survival!$B$5:$B$36,INT(($A17/H$4))+1))) | I17: =IF(($A17/I$4)>=31,0,INDEX(Data_EPA_Survival!$B$5:$B$36,INT(($A17/I$4))+1)+(($A17/I$4)-INT(($A17/I$4)))*(INDEX(Data_EPA_Survival!$B$5:$B$36,INT(($A17/I$4))+2)-INDEX(Data_EPA_Survival!$B$5:$B$36,INT(($A17/I$4))+1))) | J17: =IF(($A17/J$4)>=31,0,INDEX(Data_EPA_Survival!$B$5:$B$36,INT(($A17/J$4))+1)+(($A17/J$4)-INT(($A17/J$4)))*(INDEX(Data_EPA_Survival!$B$5:$B$36,INT(($A17/J$4))+2)-INDEX(Data_EPA_Survival!$B$5:$B$36,INT(($A17/J$4))+1))) | ... T17: =IF(($A17/T$4)>=31,0,INDEX(Data_EPA_Survival!$B$5:$B$36,INT(($A17/T$4))+1)+(($A17/T$4)-INT(($A17/T$4)))*(INDEX(Data_EPA_Survival!$B$5:$B$36,INT(($A17/T$4))+2)-INDEX(Data_EPA_Survival!$B$5:$B$36,INT(($A17/T$4))+1)))
... A51: 45 | C51: =IF(($A51/C$4)>=31,0,INDEX(Data_EPA_Survival!$B$5:$B$36,INT(($A51/C$4))+1)+(($A51/C$4)-INT(($A51/C$4)))*(INDEX(Data_EPA_Survival!$B$5:$B$36,INT(($A51/C$4))+2)-INDEX(Data_EPA_Survival!$B$5:$B$36,INT(($A51/C$4))+1))) | D51: =IF(($A51/D$4)>=31,0,INDEX(Data_EPA_Survival!$B$5:$B$36,INT(($A51/D$4))+1)+(($A51/D$4)-INT(($A51/D$4)))*(INDEX(Data_EPA_Survival!$B$5:$B$36,INT(($A51/D$4))+2)-INDEX(Data_EPA_Survival!$B$5:$B$36,INT(($A51/D$4))+1))) | E51: =IF(($A51/E$4)>=31,0,INDEX(Data_EPA_Survival!$B$5:$B$36,INT(($A51/E$4))+1)+(($A51/E$4)-INT(($A51/E$4)))*(INDEX(Data_EPA_Survival!$B$5:$B$36,INT(($A51/E$4))+2)-INDEX(Data_EPA_Survival!$B$5:$B$36,INT(($A51/E$4))+1))) | F51: =IF(($A51/F$4)>=31,0,INDEX(Data_EPA_Survival!$B$5:$B$36,INT(($A51/F$4))+1)+(($A51/F$4)-INT(($A51/F$4)))*(INDEX(Data_EPA_Survival!$B$5:$B$36,INT(($A51/F$4))+2)-INDEX(Data_EPA_Survival!$B$5:$B$36,INT(($A51/F$4))+1))) | G51: =IF(($A51/G$4)>=31,0,INDEX(Data_EPA_Survival!$B$5:$B$36,INT(($A51/G$4))+1)+(($A51/G$4)-INT(($A51/G$4)))*(INDEX(Data_EPA_Survival!$B$5:$B$36,INT(($A51/G$4))+2)-INDEX(Data_EPA_Survival!$B$5:$B$36,INT(($A51/G$4))+1))) | H51: =IF(($A51/H$4)>=31,0,INDEX(Data_EPA_Survival!$B$5:$B$36,INT(($A51/H$4))+1)+(($A51/H$4)-INT(($A51/H$4)))*(INDEX(Data_EPA_Survival!$B$5:$B$36,INT(($A51/H$4))+2)-INDEX(Data_EPA_Survival!$B$5:$B$36,INT(($A51/H$4))+1))) | I51: =IF(($A51/I$4)>=31,0,INDEX(Data_EPA_Survival!$B$5:$B$36,INT(($A51/I$4))+1)+(($A51/I$4)-INT(($A51/I$4)))*(INDEX(Data_EPA_Survival!$B$5:$B$36,INT(($A51/I$4))+2)-INDEX(Data_EPA_Survival!$B$5:$B$36,INT(($A51/I$4))+1))) | J51: =IF(($A51/J$4)>=31,0,INDEX(Data_EPA_Survival!$B$5:$B$36,INT(($A51/J$4))+1)+(($A51/J$4)-INT(($A51/J$4)))*(INDEX(Data_EPA_Survival!$B$5:$B$36,INT(($A51/J$4))+2)-INDEX(Data_EPA_Survival!$B$5:$B$36,INT(($A51/J$4))+1))) | ... T51: =IF(($A51/T$4)>=31,0,INDEX(Data_EPA_Survival!$B$5:$B$36,INT(($A51/T$4))+1)+(($A51/T$4)-INT(($A51/T$4)))*(INDEX(Data_EPA_Survival!$B$5:$B$36,INT(($A51/T$4))+2)-INDEX(Data_EPA_Survival!$B$5:$B$36,INT(($A51/T$4))+1)))
A53: k light trucks (Inputs) | C53: =Inputs!C26 | D53: =Inputs!D26 | E53: =Inputs!E26 | F53: =Inputs!F26 | G53: =Inputs!G26 | H53: =Inputs!H26 | I53: =Inputs!I26 | J53: =Inputs!J26 | ... T53: =Inputs!T26
A54: LIGHT TRUCKS: age | C54: =C3 | D54: =D3 | E54: =E3 | F54: =F3 | G54: =G3 | H54: =H3 | I54: =I3 | J54: =J3 | ... T54: =T3
A55: 0 | C55: =IF(($A55/C$53)>=31,0,INDEX(Data_EPA_Survival!$C$5:$C$36,INT(($A55/C$53))+1)+(($A55/C$53)-INT(($A55/C$53)))*(INDEX(Data_EPA_Survival!$C$5:$C$36,INT(($A55/C$53))+2)-INDEX(Data_EPA_Survival!$C$5:$C$36,INT(($A55/C$53))+1))) | D55: =IF(($A55/D$53)>=31,0,INDEX(Data_EPA_Survival!$C$5:$C$36,INT(($A55/D$53))+1)+(($A55/D$53)-INT(($A55/D$53)))*(INDEX(Data_EPA_Survival!$C$5:$C$36,INT(($A55/D$53))+2)-INDEX(Data_EPA_Survival!$C$5:$C$36,INT(($A55/D$53))+1))) | E55: =IF(($A55/E$53)>=31,0,INDEX(Data_EPA_Survival!$C$5:$C$36,INT(($A55/E$53))+1)+(($A55/E$53)-INT(($A55/E$53)))*(INDEX(Data_EPA_Survival!$C$5:$C$36,INT(($A55/E$53))+2)-INDEX(Data_EPA_Survival!$C$5:$C$36,INT(($A55/E$53))+1))) | F55: =IF(($A55/F$53)>=31,0,INDEX(Data_EPA_Survival!$C$5:$C$36,INT(($A55/F$53))+1)+(($A55/F$53)-INT(($A55/F$53)))*(INDEX(Data_EPA_Survival!$C$5:$C$36,INT(($A55/F$53))+2)-INDEX(Data_EPA_Survival!$C$5:$C$36,INT(($A55/F$53))+1))) | G55: =IF(($A55/G$53)>=31,0,INDEX(Data_EPA_Survival!$C$5:$C$36,INT(($A55/G$53))+1)+(($A55/G$53)-INT(($A55/G$53)))*(INDEX(Data_EPA_Survival!$C$5:$C$36,INT(($A55/G$53))+2)-INDEX(Data_EPA_Survival!$C$5:$C$36,INT(($A55/G$53))+1))) | H55: =IF(($A55/H$53)>=31,0,INDEX(Data_EPA_Survival!$C$5:$C$36,INT(($A55/H$53))+1)+(($A55/H$53)-INT(($A55/H$53)))*(INDEX(Data_EPA_Survival!$C$5:$C$36,INT(($A55/H$53))+2)-INDEX(Data_EPA_Survival!$C$5:$C$36,INT(($A55/H$53))+1))) | I55: =IF(($A55/I$53)>=31,0,INDEX(Data_EPA_Survival!$C$5:$C$36,INT(($A55/I$53))+1)+(($A55/I$53)-INT(($A55/I$53)))*(INDEX(Data_EPA_Survival!$C$5:$C$36,INT(($A55/I$53))+2)-INDEX(Data_EPA_Survival!$C$5:$C$36,INT(($A55/I$53))+1))) | J55: =IF(($A55/J$53)>=31,0,INDEX(Data_EPA_Survival!$C$5:$C$36,INT(($A55/J$53))+1)+(($A55/J$53)-INT(($A55/J$53)))*(INDEX(Data_EPA_Survival!$C$5:$C$36,INT(($A55/J$53))+2)-INDEX(Data_EPA_Survival!$C$5:$C$36,INT(($A55/J$53))+1))) | ... T55: =IF(($A55/T$53)>=31,0,INDEX(Data_EPA_Survival!$C$5:$C$36,INT(($A55/T$53))+1)+(($A55/T$53)-INT(($A55/T$53)))*(INDEX(Data_EPA_Survival!$C$5:$C$36,INT(($A55/T$53))+2)-INDEX(Data_EPA_Survival!$C$5:$C$36,INT(($A55/T$53))+1)))
A56: 1 | C56: =IF(($A56/C$53)>=31,0,INDEX(Data_EPA_Survival!$C$5:$C$36,INT(($A56/C$53))+1)+(($A56/C$53)-INT(($A56/C$53)))*(INDEX(Data_EPA_Survival!$C$5:$C$36,INT(($A56/C$53))+2)-INDEX(Data_EPA_Survival!$C$5:$C$36,INT(($A56/C$53))+1))) | D56: =IF(($A56/D$53)>=31,0,INDEX(Data_EPA_Survival!$C$5:$C$36,INT(($A56/D$53))+1)+(($A56/D$53)-INT(($A56/D$53)))*(INDEX(Data_EPA_Survival!$C$5:$C$36,INT(($A56/D$53))+2)-INDEX(Data_EPA_Survival!$C$5:$C$36,INT(($A56/D$53))+1))) | E56: =IF(($A56/E$53)>=31,0,INDEX(Data_EPA_Survival!$C$5:$C$36,INT(($A56/E$53))+1)+(($A56/E$53)-INT(($A56/E$53)))*(INDEX(Data_EPA_Survival!$C$5:$C$36,INT(($A56/E$53))+2)-INDEX(Data_EPA_Survival!$C$5:$C$36,INT(($A56/E$53))+1))) | F56: =IF(($A56/F$53)>=31,0,INDEX(Data_EPA_Survival!$C$5:$C$36,INT(($A56/F$53))+1)+(($A56/F$53)-INT(($A56/F$53)))*(INDEX(Data_EPA_Survival!$C$5:$C$36,INT(($A56/F$53))+2)-INDEX(Data_EPA_Survival!$C$5:$C$36,INT(($A56/F$53))+1))) | G56: =IF(($A56/G$53)>=31,0,INDEX(Data_EPA_Survival!$C$5:$C$36,INT(($A56/G$53))+1)+(($A56/G$53)-INT(($A56/G$53)))*(INDEX(Data_EPA_Survival!$C$5:$C$36,INT(($A56/G$53))+2)-INDEX(Data_EPA_Survival!$C$5:$C$36,INT(($A56/G$53))+1))) | H56: =IF(($A56/H$53)>=31,0,INDEX(Data_EPA_Survival!$C$5:$C$36,INT(($A56/H$53))+1)+(($A56/H$53)-INT(($A56/H$53)))*(INDEX(Data_EPA_Survival!$C$5:$C$36,INT(($A56/H$53))+2)-INDEX(Data_EPA_Survival!$C$5:$C$36,INT(($A56/H$53))+1))) | I56: =IF(($A56/I$53)>=31,0,INDEX(Data_EPA_Survival!$C$5:$C$36,INT(($A56/I$53))+1)+(($A56/I$53)-INT(($A56/I$53)))*(INDEX(Data_EPA_Survival!$C$5:$C$36,INT(($A56/I$53))+2)-INDEX(Data_EPA_Survival!$C$5:$C$36,INT(($A56/I$53))+1))) | J56: =IF(($A56/J$53)>=31,0,INDEX(Data_EPA_Survival!$C$5:$C$36,INT(($A56/J$53))+1)+(($A56/J$53)-INT(($A56/J$53)))*(INDEX(Data_EPA_Survival!$C$5:$C$36,INT(($A56/J$53))+2)-INDEX(Data_EPA_Survival!$C$5:$C$36,INT(($A56/J$53))+1))) | ... T56: =IF(($A56/T$53)>=31,0,INDEX(Data_EPA_Survival!$C$5:$C$36,INT(($A56/T$53))+1)+(($A56/T$53)-INT(($A56/T$53)))*(INDEX(Data_EPA_Survival!$C$5:$C$36,INT(($A56/T$53))+2)-INDEX(Data_EPA_Survival!$C$5:$C$36,INT(($A56/T$53))+1)))
A57: 2 | C57: =IF(($A57/C$53)>=31,0,INDEX(Data_EPA_Survival!$C$5:$C$36,INT(($A57/C$53))+1)+(($A57/C$53)-INT(($A57/C$53)))*(INDEX(Data_EPA_Survival!$C$5:$C$36,INT(($A57/C$53))+2)-INDEX(Data_EPA_Survival!$C$5:$C$36,INT(($A57/C$53))+1))) | D57: =IF(($A57/D$53)>=31,0,INDEX(Data_EPA_Survival!$C$5:$C$36,INT(($A57/D$53))+1)+(($A57/D$53)-INT(($A57/D$53)))*(INDEX(Data_EPA_Survival!$C$5:$C$36,INT(($A57/D$53))+2)-INDEX(Data_EPA_Survival!$C$5:$C$36,INT(($A57/D$53))+1))) | E57: =IF(($A57/E$53)>=31,0,INDEX(Data_EPA_Survival!$C$5:$C$36,INT(($A57/E$53))+1)+(($A57/E$53)-INT(($A57/E$53)))*(INDEX(Data_EPA_Survival!$C$5:$C$36,INT(($A57/E$53))+2)-INDEX(Data_EPA_Survival!$C$5:$C$36,INT(($A57/E$53))+1))) | F57: =IF(($A57/F$53)>=31,0,INDEX(Data_EPA_Survival!$C$5:$C$36,INT(($A57/F$53))+1)+(($A57/F$53)-INT(($A57/F$53)))*(INDEX(Data_EPA_Survival!$C$5:$C$36,INT(($A57/F$53))+2)-INDEX(Data_EPA_Survival!$C$5:$C$36,INT(($A57/F$53))+1))) | G57: =IF(($A57/G$53)>=31,0,INDEX(Data_EPA_Survival!$C$5:$C$36,INT(($A57/G$53))+1)+(($A57/G$53)-INT(($A57/G$53)))*(INDEX(Data_EPA_Survival!$C$5:$C$36,INT(($A57/G$53))+2)-INDEX(Data_EPA_Survival!$C$5:$C$36,INT(($A57/G$53))+1))) | H57: =IF(($A57/H$53)>=31,0,INDEX(Data_EPA_Survival!$C$5:$C$36,INT(($A57/H$53))+1)+(($A57/H$53)-INT(($A57/H$53)))*(INDEX(Data_EPA_Survival!$C$5:$C$36,INT(($A57/H$53))+2)-INDEX(Data_EPA_Survival!$C$5:$C$36,INT(($A57/H$53))+1))) | I57: =IF(($A57/I$53)>=31,0,INDEX(Data_EPA_Survival!$C$5:$C$36,INT(($A57/I$53))+1)+(($A57/I$53)-INT(($A57/I$53)))*(INDEX(Data_EPA_Survival!$C$5:$C$36,INT(($A57/I$53))+2)-INDEX(Data_EPA_Survival!$C$5:$C$36,INT(($A57/I$53))+1))) | J57: =IF(($A57/J$53)>=31,0,INDEX(Data_EPA_Survival!$C$5:$C$36,INT(($A57/J$53))+1)+(($A57/J$53)-INT(($A57/J$53)))*(INDEX(Data_EPA_Survival!$C$5:$C$36,INT(($A57/J$53))+2)-INDEX(Data_EPA_Survival!$C$5:$C$36,INT(($A57/J$53))+1))) | ... T57: =IF(($A57/T$53)>=31,0,INDEX(Data_EPA_Survival!$C$5:$C$36,INT(($A57/T$53))+1)+(($A57/T$53)-INT(($A57/T$53)))*(INDEX(Data_EPA_Survival!$C$5:$C$36,INT(($A57/T$53))+2)-INDEX(Data_EPA_Survival!$C$5:$C$36,INT(($A57/T$53))+1)))
A58: 3 | C58: =IF(($A58/C$53)>=31,0,INDEX(Data_EPA_Survival!$C$5:$C$36,INT(($A58/C$53))+1)+(($A58/C$53)-INT(($A58/C$53)))*(INDEX(Data_EPA_Survival!$C$5:$C$36,INT(($A58/C$53))+2)-INDEX(Data_EPA_Survival!$C$5:$C$36,INT(($A58/C$53))+1))) | D58: =IF(($A58/D$53)>=31,0,INDEX(Data_EPA_Survival!$C$5:$C$36,INT(($A58/D$53))+1)+(($A58/D$53)-INT(($A58/D$53)))*(INDEX(Data_EPA_Survival!$C$5:$C$36,INT(($A58/D$53))+2)-INDEX(Data_EPA_Survival!$C$5:$C$36,INT(($A58/D$53))+1))) | E58: =IF(($A58/E$53)>=31,0,INDEX(Data_EPA_Survival!$C$5:$C$36,INT(($A58/E$53))+1)+(($A58/E$53)-INT(($A58/E$53)))*(INDEX(Data_EPA_Survival!$C$5:$C$36,INT(($A58/E$53))+2)-INDEX(Data_EPA_Survival!$C$5:$C$36,INT(($A58/E$53))+1))) | F58: =IF(($A58/F$53)>=31,0,INDEX(Data_EPA_Survival!$C$5:$C$36,INT(($A58/F$53))+1)+(($A58/F$53)-INT(($A58/F$53)))*(INDEX(Data_EPA_Survival!$C$5:$C$36,INT(($A58/F$53))+2)-INDEX(Data_EPA_Survival!$C$5:$C$36,INT(($A58/F$53))+1))) | G58: =IF(($A58/G$53)>=31,0,INDEX(Data_EPA_Survival!$C$5:$C$36,INT(($A58/G$53))+1)+(($A58/G$53)-INT(($A58/G$53)))*(INDEX(Data_EPA_Survival!$C$5:$C$36,INT(($A58/G$53))+2)-INDEX(Data_EPA_Survival!$C$5:$C$36,INT(($A58/G$53))+1))) | H58: =IF(($A58/H$53)>=31,0,INDEX(Data_EPA_Survival!$C$5:$C$36,INT(($A58/H$53))+1)+(($A58/H$53)-INT(($A58/H$53)))*(INDEX(Data_EPA_Survival!$C$5:$C$36,INT(($A58/H$53))+2)-INDEX(Data_EPA_Survival!$C$5:$C$36,INT(($A58/H$53))+1))) | I58: =IF(($A58/I$53)>=31,0,INDEX(Data_EPA_Survival!$C$5:$C$36,INT(($A58/I$53))+1)+(($A58/I$53)-INT(($A58/I$53)))*(INDEX(Data_EPA_Survival!$C$5:$C$36,INT(($A58/I$53))+2)-INDEX(Data_EPA_Survival!$C$5:$C$36,INT(($A58/I$53))+1))) | J58: =IF(($A58/J$53)>=31,0,INDEX(Data_EPA_Survival!$C$5:$C$36,INT(($A58/J$53))+1)+(($A58/J$53)-INT(($A58/J$53)))*(INDEX(Data_EPA_Survival!$C$5:$C$36,INT(($A58/J$53))+2)-INDEX(Data_EPA_Survival!$C$5:$C$36,INT(($A58/J$53))+1))) | ... T58: =IF(($A58/T$53)>=31,0,INDEX(Data_EPA_Survival!$C$5:$C$36,INT(($A58/T$53))+1)+(($A58/T$53)-INT(($A58/T$53)))*(INDEX(Data_EPA_Survival!$C$5:$C$36,INT(($A58/T$53))+2)-INDEX(Data_EPA_Survival!$C$5:$C$36,INT(($A58/T$53))+1)))
A59: 4 | C59: =IF(($A59/C$53)>=31,0,INDEX(Data_EPA_Survival!$C$5:$C$36,INT(($A59/C$53))+1)+(($A59/C$53)-INT(($A59/C$53)))*(INDEX(Data_EPA_Survival!$C$5:$C$36,INT(($A59/C$53))+2)-INDEX(Data_EPA_Survival!$C$5:$C$36,INT(($A59/C$53))+1))) | D59: =IF(($A59/D$53)>=31,0,INDEX(Data_EPA_Survival!$C$5:$C$36,INT(($A59/D$53))+1)+(($A59/D$53)-INT(($A59/D$53)))*(INDEX(Data_EPA_Survival!$C$5:$C$36,INT(($A59/D$53))+2)-INDEX(Data_EPA_Survival!$C$5:$C$36,INT(($A59/D$53))+1))) | E59: =IF(($A59/E$53)>=31,0,INDEX(Data_EPA_Survival!$C$5:$C$36,INT(($A59/E$53))+1)+(($A59/E$53)-INT(($A59/E$53)))*(INDEX(Data_EPA_Survival!$C$5:$C$36,INT(($A59/E$53))+2)-INDEX(Data_EPA_Survival!$C$5:$C$36,INT(($A59/E$53))+1))) | F59: =IF(($A59/F$53)>=31,0,INDEX(Data_EPA_Survival!$C$5:$C$36,INT(($A59/F$53))+1)+(($A59/F$53)-INT(($A59/F$53)))*(INDEX(Data_EPA_Survival!$C$5:$C$36,INT(($A59/F$53))+2)-INDEX(Data_EPA_Survival!$C$5:$C$36,INT(($A59/F$53))+1))) | G59: =IF(($A59/G$53)>=31,0,INDEX(Data_EPA_Survival!$C$5:$C$36,INT(($A59/G$53))+1)+(($A59/G$53)-INT(($A59/G$53)))*(INDEX(Data_EPA_Survival!$C$5:$C$36,INT(($A59/G$53))+2)-INDEX(Data_EPA_Survival!$C$5:$C$36,INT(($A59/G$53))+1))) | H59: =IF(($A59/H$53)>=31,0,INDEX(Data_EPA_Survival!$C$5:$C$36,INT(($A59/H$53))+1)+(($A59/H$53)-INT(($A59/H$53)))*(INDEX(Data_EPA_Survival!$C$5:$C$36,INT(($A59/H$53))+2)-INDEX(Data_EPA_Survival!$C$5:$C$36,INT(($A59/H$53))+1))) | I59: =IF(($A59/I$53)>=31,0,INDEX(Data_EPA_Survival!$C$5:$C$36,INT(($A59/I$53))+1)+(($A59/I$53)-INT(($A59/I$53)))*(INDEX(Data_EPA_Survival!$C$5:$C$36,INT(($A59/I$53))+2)-INDEX(Data_EPA_Survival!$C$5:$C$36,INT(($A59/I$53))+1))) | J59: =IF(($A59/J$53)>=31,0,INDEX(Data_EPA_Survival!$C$5:$C$36,INT(($A59/J$53))+1)+(($A59/J$53)-INT(($A59/J$53)))*(INDEX(Data_EPA_Survival!$C$5:$C$36,INT(($A59/J$53))+2)-INDEX(Data_EPA_Survival!$C$5:$C$36,INT(($A59/J$53))+1))) | ... T59: =IF(($A59/T$53)>=31,0,INDEX(Data_EPA_Survival!$C$5:$C$36,INT(($A59/T$53))+1)+(($A59/T$53)-INT(($A59/T$53)))*(INDEX(Data_EPA_Survival!$C$5:$C$36,INT(($A59/T$53))+2)-INDEX(Data_EPA_Survival!$C$5:$C$36,INT(($A59/T$53))+1)))
A60: 5 | C60: =IF(($A60/C$53)>=31,0,INDEX(Data_EPA_Survival!$C$5:$C$36,INT(($A60/C$53))+1)+(($A60/C$53)-INT(($A60/C$53)))*(INDEX(Data_EPA_Survival!$C$5:$C$36,INT(($A60/C$53))+2)-INDEX(Data_EPA_Survival!$C$5:$C$36,INT(($A60/C$53))+1))) | D60: =IF(($A60/D$53)>=31,0,INDEX(Data_EPA_Survival!$C$5:$C$36,INT(($A60/D$53))+1)+(($A60/D$53)-INT(($A60/D$53)))*(INDEX(Data_EPA_Survival!$C$5:$C$36,INT(($A60/D$53))+2)-INDEX(Data_EPA_Survival!$C$5:$C$36,INT(($A60/D$53))+1))) | E60: =IF(($A60/E$53)>=31,0,INDEX(Data_EPA_Survival!$C$5:$C$36,INT(($A60/E$53))+1)+(($A60/E$53)-INT(($A60/E$53)))*(INDEX(Data_EPA_Survival!$C$5:$C$36,INT(($A60/E$53))+2)-INDEX(Data_EPA_Survival!$C$5:$C$36,INT(($A60/E$53))+1))) | F60: =IF(($A60/F$53)>=31,0,INDEX(Data_EPA_Survival!$C$5:$C$36,INT(($A60/F$53))+1)+(($A60/F$53)-INT(($A60/F$53)))*(INDEX(Data_EPA_Survival!$C$5:$C$36,INT(($A60/F$53))+2)-INDEX(Data_EPA_Survival!$C$5:$C$36,INT(($A60/F$53))+1))) | G60: =IF(($A60/G$53)>=31,0,INDEX(Data_EPA_Survival!$C$5:$C$36,INT(($A60/G$53))+1)+(($A60/G$53)-INT(($A60/G$53)))*(INDEX(Data_EPA_Survival!$C$5:$C$36,INT(($A60/G$53))+2)-INDEX(Data_EPA_Survival!$C$5:$C$36,INT(($A60/G$53))+1))) | H60: =IF(($A60/H$53)>=31,0,INDEX(Data_EPA_Survival!$C$5:$C$36,INT(($A60/H$53))+1)+(($A60/H$53)-INT(($A60/H$53)))*(INDEX(Data_EPA_Survival!$C$5:$C$36,INT(($A60/H$53))+2)-INDEX(Data_EPA_Survival!$C$5:$C$36,INT(($A60/H$53))+1))) | I60: =IF(($A60/I$53)>=31,0,INDEX(Data_EPA_Survival!$C$5:$C$36,INT(($A60/I$53))+1)+(($A60/I$53)-INT(($A60/I$53)))*(INDEX(Data_EPA_Survival!$C$5:$C$36,INT(($A60/I$53))+2)-INDEX(Data_EPA_Survival!$C$5:$C$36,INT(($A60/I$53))+1))) | J60: =IF(($A60/J$53)>=31,0,INDEX(Data_EPA_Survival!$C$5:$C$36,INT(($A60/J$53))+1)+(($A60/J$53)-INT(($A60/J$53)))*(INDEX(Data_EPA_Survival!$C$5:$C$36,INT(($A60/J$53))+2)-INDEX(Data_EPA_Survival!$C$5:$C$36,INT(($A60/J$53))+1))) | ... T60: =IF(($A60/T$53)>=31,0,INDEX(Data_EPA_Survival!$C$5:$C$36,INT(($A60/T$53))+1)+(($A60/T$53)-INT(($A60/T$53)))*(INDEX(Data_EPA_Survival!$C$5:$C$36,INT(($A60/T$53))+2)-INDEX(Data_EPA_Survival!$C$5:$C$36,INT(($A60/T$53))+1)))
A61: 6 | C61: =IF(($A61/C$53)>=31,0,INDEX(Data_EPA_Survival!$C$5:$C$36,INT(($A61/C$53))+1)+(($A61/C$53)-INT(($A61/C$53)))*(INDEX(Data_EPA_Survival!$C$5:$C$36,INT(($A61/C$53))+2)-INDEX(Data_EPA_Survival!$C$5:$C$36,INT(($A61/C$53))+1))) | D61: =IF(($A61/D$53)>=31,0,INDEX(Data_EPA_Survival!$C$5:$C$36,INT(($A61/D$53))+1)+(($A61/D$53)-INT(($A61/D$53)))*(INDEX(Data_EPA_Survival!$C$5:$C$36,INT(($A61/D$53))+2)-INDEX(Data_EPA_Survival!$C$5:$C$36,INT(($A61/D$53))+1))) | E61: =IF(($A61/E$53)>=31,0,INDEX(Data_EPA_Survival!$C$5:$C$36,INT(($A61/E$53))+1)+(($A61/E$53)-INT(($A61/E$53)))*(INDEX(Data_EPA_Survival!$C$5:$C$36,INT(($A61/E$53))+2)-INDEX(Data_EPA_Survival!$C$5:$C$36,INT(($A61/E$53))+1))) | F61: =IF(($A61/F$53)>=31,0,INDEX(Data_EPA_Survival!$C$5:$C$36,INT(($A61/F$53))+1)+(($A61/F$53)-INT(($A61/F$53)))*(INDEX(Data_EPA_Survival!$C$5:$C$36,INT(($A61/F$53))+2)-INDEX(Data_EPA_Survival!$C$5:$C$36,INT(($A61/F$53))+1))) | G61: =IF(($A61/G$53)>=31,0,INDEX(Data_EPA_Survival!$C$5:$C$36,INT(($A61/G$53))+1)+(($A61/G$53)-INT(($A61/G$53)))*(INDEX(Data_EPA_Survival!$C$5:$C$36,INT(($A61/G$53))+2)-INDEX(Data_EPA_Survival!$C$5:$C$36,INT(($A61/G$53))+1))) | H61: =IF(($A61/H$53)>=31,0,INDEX(Data_EPA_Survival!$C$5:$C$36,INT(($A61/H$53))+1)+(($A61/H$53)-INT(($A61/H$53)))*(INDEX(Data_EPA_Survival!$C$5:$C$36,INT(($A61/H$53))+2)-INDEX(Data_EPA_Survival!$C$5:$C$36,INT(($A61/H$53))+1))) | I61: =IF(($A61/I$53)>=31,0,INDEX(Data_EPA_Survival!$C$5:$C$36,INT(($A61/I$53))+1)+(($A61/I$53)-INT(($A61/I$53)))*(INDEX(Data_EPA_Survival!$C$5:$C$36,INT(($A61/I$53))+2)-INDEX(Data_EPA_Survival!$C$5:$C$36,INT(($A61/I$53))+1))) | J61: =IF(($A61/J$53)>=31,0,INDEX(Data_EPA_Survival!$C$5:$C$36,INT(($A61/J$53))+1)+(($A61/J$53)-INT(($A61/J$53)))*(INDEX(Data_EPA_Survival!$C$5:$C$36,INT(($A61/J$53))+2)-INDEX(Data_EPA_Survival!$C$5:$C$36,INT(($A61/J$53))+1))) | ... T61: =IF(($A61/T$53)>=31,0,INDEX(Data_EPA_Survival!$C$5:$C$36,INT(($A61/T$53))+1)+(($A61/T$53)-INT(($A61/T$53)))*(INDEX(Data_EPA_Survival!$C$5:$C$36,INT(($A61/T$53))+2)-INDEX(Data_EPA_Survival!$C$5:$C$36,INT(($A61/T$53))+1)))
A62: 7 | C62: =IF(($A62/C$53)>=31,0,INDEX(Data_EPA_Survival!$C$5:$C$36,INT(($A62/C$53))+1)+(($A62/C$53)-INT(($A62/C$53)))*(INDEX(Data_EPA_Survival!$C$5:$C$36,INT(($A62/C$53))+2)-INDEX(Data_EPA_Survival!$C$5:$C$36,INT(($A62/C$53))+1))) | D62: =IF(($A62/D$53)>=31,0,INDEX(Data_EPA_Survival!$C$5:$C$36,INT(($A62/D$53))+1)+(($A62/D$53)-INT(($A62/D$53)))*(INDEX(Data_EPA_Survival!$C$5:$C$36,INT(($A62/D$53))+2)-INDEX(Data_EPA_Survival!$C$5:$C$36,INT(($A62/D$53))+1))) | E62: =IF(($A62/E$53)>=31,0,INDEX(Data_EPA_Survival!$C$5:$C$36,INT(($A62/E$53))+1)+(($A62/E$53)-INT(($A62/E$53)))*(INDEX(Data_EPA_Survival!$C$5:$C$36,INT(($A62/E$53))+2)-INDEX(Data_EPA_Survival!$C$5:$C$36,INT(($A62/E$53))+1))) | F62: =IF(($A62/F$53)>=31,0,INDEX(Data_EPA_Survival!$C$5:$C$36,INT(($A62/F$53))+1)+(($A62/F$53)-INT(($A62/F$53)))*(INDEX(Data_EPA_Survival!$C$5:$C$36,INT(($A62/F$53))+2)-INDEX(Data_EPA_Survival!$C$5:$C$36,INT(($A62/F$53))+1))) | G62: =IF(($A62/G$53)>=31,0,INDEX(Data_EPA_Survival!$C$5:$C$36,INT(($A62/G$53))+1)+(($A62/G$53)-INT(($A62/G$53)))*(INDEX(Data_EPA_Survival!$C$5:$C$36,INT(($A62/G$53))+2)-INDEX(Data_EPA_Survival!$C$5:$C$36,INT(($A62/G$53))+1))) | H62: =IF(($A62/H$53)>=31,0,INDEX(Data_EPA_Survival!$C$5:$C$36,INT(($A62/H$53))+1)+(($A62/H$53)-INT(($A62/H$53)))*(INDEX(Data_EPA_Survival!$C$5:$C$36,INT(($A62/H$53))+2)-INDEX(Data_EPA_Survival!$C$5:$C$36,INT(($A62/H$53))+1))) | I62: =IF(($A62/I$53)>=31,0,INDEX(Data_EPA_Survival!$C$5:$C$36,INT(($A62/I$53))+1)+(($A62/I$53)-INT(($A62/I$53)))*(INDEX(Data_EPA_Survival!$C$5:$C$36,INT(($A62/I$53))+2)-INDEX(Data_EPA_Survival!$C$5:$C$36,INT(($A62/I$53))+1))) | J62: =IF(($A62/J$53)>=31,0,INDEX(Data_EPA_Survival!$C$5:$C$36,INT(($A62/J$53))+1)+(($A62/J$53)-INT(($A62/J$53)))*(INDEX(Data_EPA_Survival!$C$5:$C$36,INT(($A62/J$53))+2)-INDEX(Data_EPA_Survival!$C$5:$C$36,INT(($A62/J$53))+1))) | ... T62: =IF(($A62/T$53)>=31,0,INDEX(Data_EPA_Survival!$C$5:$C$36,INT(($A62/T$53))+1)+(($A62/T$53)-INT(($A62/T$53)))*(INDEX(Data_EPA_Survival!$C$5:$C$36,INT(($A62/T$53))+2)-INDEX(Data_EPA_Survival!$C$5:$C$36,INT(($A62/T$53))+1)))
