Workbook

Sheet Cover
B2: Copart, Inc. (NASDAQ: CPRT)
B3: Revenue architecture, three-statement model, DCF and reverse DCF — Harvard pitch team, October 2026
B5: Ticker | D5: NASDAQ: $CPRT | F5: Colour and label legend
B6: Current share price (26 Sep 2026) | D6: 29.95 | F6: Blue: typed input, with label and source | H6: Owner-entered close — the one typed price in the workbook. DCF H118, the WACC build (Reverse DCF S5) and the Summary read this cell; a rebuild keeps whatever is typed here
B7: Price target (DCF implied share price, selected case) | D7: =DCF!H98 | F7: Black: formula | H7: DCF equity bridge on the Cover statistics and fully diluted shares
B8: Implied upside / (downside) | D8: =D7/D6-1 | F8: Green: link from another tab
B9: Key statistics — the hub: the DCF bridge, the WACC build and the Summary read these cells | F9: Red: toggle, probability or scenario selector
B10: Market capitalisation ($m) | D10: =D6*D15 | F10: Grey italic: notes and sources | H10: Price × fully diluted shares; feeds the WACC build (Reverse DCF S7)
B11: Enterprise value ($m) | D11: =D10-D12+D13+D14 | F11: Labels: VERIFIED · MEASURED · FITTED · CALIBRATED · ASSUMED · UNVERIFIED · ENGINE | H11: Market cap − cash & HTM + lease debt + non-controlling interest
B12: Cash & held-to-maturity securities, 31 Jul 2026 ($m) | D12: ='D 10-K FY26'!C12+'D 10-K FY26'!C13 | F12: Tab map | H12: 10-K balance sheet (D 10-K FY26: 1,907.9 + 2,581.9); feeds DCF H107
B13: Debt: lease liabilities, 31 Jul 2026 ($m) | D13: ='3SM'!H77 | F13: Key Drivers | G13: the numbers the theses turn on | H13: 3SM balance sheet (PitchBook / 10-K): 15.2 current + 73.2 non-current; no funded debt. Feeds DCF H108 and the WACC build (S8)
B14: Non-controlling interest, 31 Jul 2026 ($m) | D14: ='3SM'!H72 | F14: Summary | G14: headline financials, Street Δ, component delta to Street | H14: 3SM balance sheet; feeds DCF H109
B15: Fully diluted shares (mn) = basic + treasury-method options + RSUs | D15: =D16+D17+D18 | F15: RPM | G15: one-page revenue build; scenario dropdown in D3 | H15: Feeds DCF H112 and the WACC build (Reverse DCF S6)
B16: Basic shares outstanding, 31 Jul 2026 (mn) | D16: ='D 10-K FY26'!C5 | F16: 3SM | G16: three statements FY22A–FY31E with schedules; feeds the DCF | H16: 10-K Note 12: 926,298,293 shares at 31 Jul 2026
B17: Net shares from options, treasury method (mn): N × max(0, 1 − K/P) | D17: ='D 10-K FY26'!C6/1000*MAX(0,1-'D 10-K FY26'!D6/D6) | F17: DCF / Reverse DCF | G17: valuation; WACC and tax build in Reverse DCF columns R–X | H17: 10-K Note 12: 12.759m options at a $24.19 weighted-average exercise price; P = the price in D6
B18: Unvested RSUs (mn) | D18: =IF(ISNUMBER('D 10-K FY26'!C8),'D 10-K FY26'!C8/1000,0) | F18: E1–E6 | G18: engines: fleet, claims, carriers, aftermarket, fees, branches | H18: RSU count not parsed from the filing text; enter it from Note 12 on D 10-K FY26
B19: EV / FY2026A adjusted EBITDA (x) | D19: =D11/D22 | F19: Scenarios / Street | G19: seven cases on one base; broker assumptions
B20: Price / FY2026A diluted EPS (x) | D20: =D6/'3SM'!H28 | F20: Sources / Checks | G20: every input with its source; live checks | H20: 3SM FY2026A diluted EPS
B21: FY2026A revenue ($m) | D21: =RPM!H6 | F21: D … | G21: data tabs with sources and dates
B22: FY2026A adjusted EBITDA ($m) | D22: ='3SM'!H18 | H22: 3SM: EBIT + D&A (Barclays definition)
B23: FY2027E legacy service revenue, selected case ($m) | D23: =RPM!I10
B24: Δ to JPMorgan FY27E service revenue ($m) | D24: =RPM!D50
B25: Selected scenario (dropdown on RPM D3) | D25: =RPM!D3
B26: WACC (bottom-up build, Reverse DCF R–X) | D26: ='WACC, Tax, and Reverse DCF'!N31
B27: Structural effective tax rate | D27: ='WACC, Tax, and Reverse DCF'!N39

Sheet Key Drivers
B1: Key Drivers (all cells link to the engines; labels and sources travel with them)
B2: Green = link. Change an input on its engine tab, not here. FQ4 FY26 is the last reported quarter; FQ1 FY27 is the first forecast quarter.
D4: Value | E4: Unit | F4: Label | H4: Source / where it lives
B5: Thesis 1 — coverage persistence (E2 block F, D Coverage)
B6: Motor-vehicle-insurance CPI, latest month y/y (Aug 2026) | D6: ='D Coverage'!Q17 | E6: % | F6: VERIFIED | H6: BLS CUUR0000SETE, raw/bls; the premium index is falling
B7: Premium growth used for FY27 (selected path; E2 row 127 selects BLS trend or S&P-consistent) | D7: ='E2 Claims & Totals'!D123 | E7: % | F7: selected | H7: E2 D123
B8: Average hourly earnings growth, latest year | D8: ='E2 Claims & Totals'!D124 | E8: % | F8: VERIFIED | H8: BLS CES0500000003
B9: Premium burden 2023 (level at which households left) / 2026 to date (2025 = 1) | D9: ='E2 Claims & Totals'!J108 | E9: x | F9: MEASURED | H9: E2 row 108; 2026 value in M108 (0.956): still 10% above 2023 after the 2026 premium decline
B10: First quarter the burden falls below its 2023 level, selected path | D10: ='E2 Claims & Totals'!D131 | F10: MEASURED | H10: E2 D131; "beyond FQ4 FY28" on the S&P-consistent path
B11: S&P auto combined ratio path 2025P / 2026P / 2027P | D11: ='D Coverage'!D20 | E11: ratio | F11: VERIFIED (republication) | H11: D Coverage rows 20–22: 94.5 / 97.1 / 98.9, breaching 100 in 2028 (Carrier Management, 6 Jan 2026)
B12: Uninsured-motorist rate 2017 / 2023 | D12: ='D Coverage'!D8 | E12: % | F12: VERIFIED endpoints | H12: IRC release 20 Feb 2025; 2023 = 15.4% (D Coverage J8)
B13: Physical-damage coverage index 2017 (2025 = 1.000; the 2017–23 change is the measured coverage decline) | D13: ='E2 Claims & Totals'!D107 | E13: x | F13: MEASURED | H13: E2 row 107; collision share 76–77% flat 2021–23, so the decline is the uninsured leg
B14: Share of insured drivers with collision coverage, 2021 / 2022 / 2023 | D14: ='D Coverage'!H9 | E14: % | F14: VERIFIED (republication) | H14: III via Wayback snapshots 2024 and 2025 plus the live page: 76% / 77% / 77%
B15: Two-point coverage response to premium burden (ε) | D15: ='E2 Claims & Totals'!D110 | E15: x | F15: UNVERIFIED | H15: E2 D110; n = 2
B16: Street-implied FY27 coverage recovery r (reverse-solved to JPM) | D16: ='E2 Claims & Totals'!D126 | E16: % | F16: MEASURED | H16: E2 D124: what the Street number needs
B17: Coverage ratio FQ1 FY27: sticky / premium-response / recovery | D17: ='E2 Claims & Totals'!H116 | E17: x | F17: paths | H17: E2 rows 116–118 (H117, H118 for the other paths)
B18: CCC total claim volume y/y, 2024 / 2025 | D18: ='D Coverage'!K10 | E18: % | F18: VERIFIED | H18: D Coverage K10 / L10 (2025 = −3.3%)
B20: Thesis 2 — aftermarket substitution (E4)
B21: Aftermarket share of replacement-part dollars, 2025 | D21: ='E4 Aftermarket'!D47 | E21: % | F21: VERIFIED | H21: CCC Crash Course 2026 (21.0% in 2024)
B22: Recycled share of replacement-part dollars, 2025 | D22: ='E4 Aftermarket'!D48 | E22: % | F22: VERIFIED | H22: CCC (10.7% in 2024)
B23: Aftermarket price relative to OEM at the anchor | D23: ='E4 Aftermarket'!D50 | E23: x | F23: VERIFIED (historical) | H23: Mitchell 2016 discounts, mean 27%; recycled set equal at the anchor
B24: Aftermarket relative-price drift per year (PartsTrader: OEM +4.3%, aftermarket <1%) | D24: ='E4 Aftermarket'!D68 | E24: % | F24: VERIFIED (trend, one year) | H24: E4 D68
B25: Aftermarket price relative to OEM by FQ4 FY28 (recycled stays at 0.73) | D25: ='E4 Aftermarket'!O9 | E25: x | F25: derived | H25: E4 row 9
B26: Sourcing path selector (1 observed trend, 2 memo stress) | D26: ='E4 Aftermarket'!D64 | F26: TOGGLE | H26: E4 D64
B27: Cumulative aftermarket share shift at FQ4 FY27 (selected path) | D27: ='E4 Aftermarket'!K7 | E27: pts | F27: path | H27: E4 row 7
B28: Complete repair-bill change at FQ4 FY27 | D28: ='E4 Aftermarket'!K14 | E28: % | F28: derived | H28: E4 row 14
B29: Change in total-loss units at FQ4 FY27 | D29: ='E4 Aftermarket'!K40 | E29: % | F29: ENGINE-derived η × bill change | H29: E4 row 40
B30: Change in auction price at FQ4 FY27 | D30: ='E4 Aftermarket'!K41 | E30: % | F30: ASSUMED scaling | H30: E4 row 41
B31: Memo stress case (5.5 pts) at sourced prices: bill change / units | D31: ='E4 Aftermarket'!D31 | E31: % | F31: derived | H31: E4 D31 / E31; engine basket reproduces 1.03% in D30
B33: Thesis 3 — carrier allocation (E3)
B34: Copart share of the insured total-loss pool, FQ4 FY26 | D34: ='E3 Carriers'!G43 | E34: % | F34: reconstructed | H34: E3 row 43 (frozen weights × inherited allocation)
B35: Share FQ4 FY27, base (known runoff only) | D35: ='E3 Carriers'!K43 | E35: % | F35: scenario | H35: E3 row 43
B36: Share FQ4 FY27, thesis 3 (probability-weighted moves) | D36: ='E3 Carriers'!K44 | E36: % | F36: scenario | H36: E3 row 44; memo: 56.6% → 55.3%
B37: Progressive allocation to Copart, FQ4 FY26 / FQ4 FY27 | D37: ='E3 Carriers'!G20 | E37: share | F37: UNVERIFIED path | H37: E3 row 20 (K20 for FY27)
B38: Expected move: State Farm / Other (pts) | D38: ='E3 Carriers'!F77 | E38: pts | F38: UNVERIFIED | H38: E3 rows 77–78: −5 pts × 45% each
B39: Progressive move: effect on FQ4 FY26 service revenue | D39: ='E3 Carriers'!D83 | E39: % | F39: MEASURED chain | H39: E3 row 83 (E83 = % of total revenue)
B40: Listed-inventory split, Copart share of duopoly (4 nights) | D40: ='E3 Carriers'!G45 | E40: % | F40: MEASURED | H40: data/csv/duopoly_daily.csv
B41: IAA acreage (owned + leased) | D41: ='E3 Carriers'!E86 | E41: acres | F41: VERIFIED | H41: RB Global FY2025 10-K
B42: RB Global automotive lots, Q2 2026 y/y | D42: ='E3 Carriers'!E94 | E42: % | F42: VERIFIED | H42: RB Global 10-Q
B43: Effective seller commission, thesis 3, FQ4 FY27 | D43: ='E3 Carriers'!K56 | E43: % | F43: UNVERIFIED (Barclays 4% base) | H43: E3 row 56
...

Sheet Summary
B1: Copart, Inc. — Summary: headline financials, Street comparison and the component delta to Street
B2: Every cell links to the 3SM, DCF, Scenarios, Street, Cover or D Barclays tab (green). Fiscal years end 31 July. $M except per share. Barclays = 11 Sep 2026 model (Underweight, $25). – = no line for that year.
C4: Units | D4: Historicals | G4: Projected | L4: Notes / sources
B5: Headline financials — 3SM, selected case (RPM D3) | D5: FY2024A | E5: FY2025A | F5: FY2026A | G5: FY2027E | H5: FY2028E | I5: FY2029E
B6: Revenue | C6: $M | D6: ='3SM'!F8 | E6: ='3SM'!G8 | F6: ='3SM'!H8 | G6: ='3SM'!I8 | H6: ='3SM'!J8 | I6: ='3SM'!K8 | L6: 3SM row 8 (RPM)
B7: y/y growth | C7: % | D7: – | E7: =IF(D6=0,0,E6/D6-1) | F7: =IF(E6=0,0,F6/E6-1) | G7: =IF(F6=0,0,G6/F6-1) | H7: =IF(G6=0,0,H6/G6-1) | I7: =IF(H6=0,0,I6/H6-1)
B8: Adjusted EBITDA | C8: $M | D8: ='3SM'!F18 | E8: ='3SM'!G18 | F8: ='3SM'!H18 | G8: ='3SM'!I18 | H8: ='3SM'!J18 | I8: ='3SM'!K18 | L8: 3SM row 18 (EBIT + D&A, Barclays definition)
B9: margin | C9: % | D9: =IF(D6=0,0,D8/D6) | E9: =IF(E6=0,0,E8/E6) | F9: =IF(F6=0,0,F8/F6) | G9: =IF(G6=0,0,G8/G6) | H9: =IF(H6=0,0,H8/H6) | I9: =IF(I6=0,0,I8/I6)
B10: GAAP diluted EPS | C10: $ | D10: ='3SM'!F28 | E10: ='3SM'!G28 | F10: ='3SM'!H28 | G10: ='3SM'!I28 | H10: ='3SM'!J28 | I10: ='3SM'!K28 | L10: 3SM row 28
B11: y/y growth | C11: % | D11: – | E11: =IF(D10=0,0,E10/D10-1) | F11: =IF(E10=0,0,F10/E10-1) | G11: =IF(F10=0,0,G10/F10-1) | H11: =IF(G10=0,0,H10/G10-1) | I11: =IF(H10=0,0,I10/H10-1)
B12: Free cash flow (CFO + capex) | C12: $M | D12: ='3SM'!F112 | E12: ='3SM'!G112 | F12: ='3SM'!H112 | G12: ='3SM'!I112 | H12: ='3SM'!J112 | I12: ='3SM'!K112 | L12: 3SM row 112
B13: margin | C13: % | D13: =IF(D6=0,0,D12/D6) | E13: =IF(E6=0,0,E12/E6) | F13: =IF(F6=0,0,F12/F6) | G13: =IF(G6=0,0,G12/G6) | H13: =IF(H6=0,0,H12/H6) | I13: =IF(I6=0,0,I12/I6)
B14: Unlevered free cash flow (DCF) | C14: $M | D14: =DCF!F59 | E14: =DCF!G59 | F14: =DCF!H59 | G14: =DCF!I59 | H14: =DCF!J59 | I14: =DCF!K59 | L14: DCF row 63: NOPAT + D&A + SBC − capex − ΔNWC; D&A, SBC, capex and ΔNWC read the 3SM
B15: margin | C15: % | D15: =IF(D6=0,0,D14/D6) | E15: =IF(E6=0,0,E14/E6) | F15: =IF(F6=0,0,F14/F6) | G15: =IF(G6=0,0,G14/G6) | H15: =IF(H6=0,0,H14/H6) | I15: =IF(I6=0,0,I14/I6)
B16: Street — Barclays model (11 Sep 2026) and consensus EPS; % Δ = 3SM ÷ Street − 1 | D16: FY2024A | E16: FY2025A | F16: FY2026A | G16: FY2027E | H16: FY2028E | I16: FY2029E
B17: Barclays revenue | C17: $M | D17: – | E17: – | F17: ='D Barclays'!D5 | G17: ='D Barclays'!E5 | H17: ='D Barclays'!F5 | I17: ='D Barclays'!G5 | L17: D Barclays (numeric extraction from the licensed report held locally; FY2026A = reported)
B18: y/y growth | C18: % | D18: – | E18: – | F18: – | G18: =IF(F17=0,0,G17/F17-1) | H18: =IF(G17=0,0,H17/G17-1) | I18: =IF(H17=0,0,I17/H17-1)
B19: % Δ 3SM vs Barclays | C19: % | D19: – | E19: – | F19: =IF(F17=0,0,F6/F17-1) | G19: =IF(G17=0,0,G6/G17-1) | H19: =IF(H17=0,0,H6/H17-1) | I19: =IF(I17=0,0,I6/I17-1)
B20: Barclays adjusted EBITDA | C20: $M | D20: – | E20: – | F20: ='D Barclays'!D6 | G20: ='D Barclays'!E6 | H20: ='D Barclays'!F6 | I20: ='D Barclays'!G6
B21: margin | C21: % | D21: – | E21: – | F21: =IF(F17=0,0,F20/F17) | G21: =IF(G17=0,0,G20/G17) | H21: =IF(H17=0,0,H20/H17) | I21: =IF(I17=0,0,I20/I17)
B22: % Δ 3SM vs Barclays | C22: % | D22: – | E22: – | F22: =IF(F20=0,0,F8/F20-1) | G22: =IF(G20=0,0,G8/G20-1) | H22: =IF(H20=0,0,H8/H20-1) | I22: =IF(I20=0,0,I8/I20-1)
B23: Barclays diluted EPS | C23: $ | D23: – | E23: – | F23: ='D Barclays'!D10 | G23: ='D Barclays'!E10 | H23: ='D Barclays'!F10 | I23: ='D Barclays'!G10
B24: % Δ 3SM vs Barclays | C24: % | D24: – | E24: – | F24: =IF(F23=0,0,F10/F23-1) | G24: =IF(G23=0,0,G10/G23-1) | H24: =IF(H23=0,0,H10/H23-1) | I24: =IF(I23=0,0,I10/I23-1)
B25: DCF diluted EPS (owner's DCF row 41; the DCF keeps its own cost build) | C25: $ | D25: – | E25: – | F25: =DCF!H41 | G25: =DCF!I41 | H25: =DCF!J41 | I25: =DCF!K41 | L25: DCF row 41 (DCF EBIT build differs from the 3SM; see 3SM schedule 9)
B26: % Δ DCF EPS vs Barclays | C26: % | D26: – | E26: – | F26: =IF(F23=0,0,F25/F23-1) | G26: =IF(G23=0,0,G25/G23-1) | H26: =IF(H23=0,0,H25/H23-1) | I26: =IF(I23=0,0,I25/I23-1) | L26: Summary row 23 holds Barclays EPS
B27: Broker total revenue — BNP Paribas (Outperform, $40) | C27: $M | D27: – | E27: – | F27: – | G27: =Street!E9 | H27: =Street!E10 | I27: – | L27: Street tab rows 9–10 (named-broker extractions; report dates in Street row 5)
B28: Broker total revenue — J.P. Morgan | C28: $M | D28: – | E28: – | F28: – | G28: =Street!F9 | H28: =Street!F10 | I28: – | L28: Street tab rows 9–10 (named-broker extractions; report dates in Street row 5)
B29: Broker total revenue — BofA Global Research | C29: $M | D29: – | E29: – | F29: – | G29: =Street!G9 | H29: =Street!G10 | I29: – | L29: Street tab rows 9–10 (named-broker extractions; report dates in Street row 5)
B30: Broker total revenue — Barclays, 25 Aug 2026 note | C30: $M | D30: – | E30: – | F30: – | G30: =Street!I9 | H30: =Street!I10 | I30: – | L30: Street tab rows 9–10 (named-broker extractions; report dates in Street row 5)
B31: Component delta to Street — legacy service revenue by case ($M; engines run FY27–28) and the EBITDA bridge to Barclays | D31: FY2024A | E31: FY2025A | F31: FY2026A | G31: FY2027E | H31: FY2028E | I31: FY2029E
B32: Street-implied (case 0): known runoff, coverage recovering to the Street path | C32: $M | D32: – | E32: – | F32: – | G32: =Scenarios!Q16 | H32: =Scenarios!R16 | I32: – | L32: Scenarios Q/R16; the recovery rate is reverse-solved so FY27 equals JPMorgan
B33: JPMorgan FY27E legacy service revenue, 11 Sep 2026 (ex-ACV) | C33: $M | D33: – | E33: – | F33: – | G33: =Scenarios!$D$108 | H33: – | I33: – | L33: Scenarios D108 ← D Facts (licensed report held locally); JPMorgan publishes no FY28 service line
B34: Thesis 1 — coverage persistence: case 1 (known facts, sticky coverage) − case 0 | C34: $M | D34: – | E34: – | F34: – | G34: =Scenarios!Q29-Scenarios!Q16 | H34: =Scenarios!R29-Scenarios!R16 | I34: – | L34: Scenarios rows 29 − 16
B35: Thesis 2 — aftermarket substitution: thesis 2 case − case 1 | C35: $M | D35: – | E35: – | F35: – | G35: =Scenarios!Q55-Scenarios!Q29 | H35: =Scenarios!R55-Scenarios!R29 | I35: – | L35: Scenarios rows 55 − 29
B36: Thesis 3 — carrier reallocation (probability-weighted): thesis 3 case − case 1 | C36: $M | D36: – | E36: – | F36: – | G36: =Scenarios!Q68-Scenarios!Q29 | H36: =Scenarios!R68-Scenarios!R29 | I36: – | L36: Scenarios rows 68 − 29
B37: Interaction (all three − case 0 − sum of the three parts; exact on the common base) | C37: $M | D37: – | E37: – | F37: – | G37: =Scenarios!Q81-Scenarios!Q16-G34-G35-G36 | H37: =Scenarios!R81-Scenarios!R16-H34-H35-H36 | I37: –
B38: All three vs Street-implied | C38: $M | D38: – | E38: – | F38: – | G38: =Scenarios!Q81-Scenarios!Q16 | H38: =Scenarios!R81-Scenarios!R16 | I38: – | L38: Scenarios rows 81 − 16
B39: All three vs JPMorgan, % | C39: % | D39: – | E39: – | F39: – | G39: =Scenarios!H117 | H39: – | I39: – | L39: Scenarios H117
B40: Selected case on the RPM (D3): service revenue | C40: $M | D40: – | E40: – | F40: – | G40: =RPM!I10 | H40: =RPM!J10 | I40: – | L40: RPM I10 / J10 → 3SM
B41: Δ selected case vs Street-implied | C41: $M | D41: – | E41: – | F41: – | G41: =G40-G32 | H41: =H40-H32 | I41: –
...

Sheet MODEL -------->

Sheet RPM
B1: Copart, Inc. (NASDAQ: CPRT)
B2: Revenue = fee units * service revenue per unit + principal vehicle sales. In $M
B3: Scenario selector — click D3 and choose a case (drives rows 10, 12, 21 for FY27–28; case index in I3) | D3: 6 · All three — sticky coverage + aftermarket + carriers | I3: =MATCH(D3,$U$5:$U$11,0)
C4: Units | D4: Historicals | I4: Projected | U4: Scenario options (list source for the D3 dropdown; do not edit)
B5: Reported revenue | D5: FY2022A | E5: FY2023A | F5: FY2024A | G5: FY2025A | H5: FY2026A | I5: FY2027E | J5: FY2028E | K5: FY2029E | L5: FY2030E | M5: FY2031E | N5: FY26–31 CAGR | U5: 1 · Case 0 — Street-implied (coverage recovers to JPM)
B6: Total Revenue | C6: $M | D6: ='PB IS (Annual)'!Q14/1000 | E6: ='PB IS (Annual)'!P14/1000 | F6: ='PB IS (Annual)'!O14/1000 | G6: ='PB IS (Annual)'!N14/1000 | H6: ='PB IS (Annual)'!M14/1000 | I6: =I10+I12 | J6: =J10+J12 | K6: =K10+K12 | L6: =L10+L12 | M6: =M10+M12 | N6: =IFERROR((M6/H6)^(1/5)-1,"") | U6: 2 · Case 1 — Known facts, sticky coverage (thesis 1)
B7: y/y growth | C7: % | D7: -- | E7: =E6/D6-1 | F7: =F6/E6-1 | G7: =G6/F6-1 | H7: =H6/G6-1 | I7: =I6/H6-1 | J7: =J6/I6-1 | K7: =K6/J6-1 | L7: =L6/K6-1 | M7: =M6/L6-1 | U7: 3 · Case 1b — Premium-response coverage
U8: 4 · Thesis 2 — aftermarket substitution on case 1
B9: Revenue by type | U9: 5 · Thesis 3 — carrier moves on case 1
B10: Service revenue (fee-based) | C10: $M | D10: 2881.7 | E10: 3199.6 | F10: 3561 | G10: 3968.7 | H10: 3969.5 | I10: =Scenarios!Q126 | J10: =Scenarios!R126 | K10: =J10*(1+$D$43) | L10: =K10*(1+$D$43) | M10: =L10*(1+$D$43) | N10: =IFERROR((M10/H10)^(1/5)-1,"") | P10: FY27–28 from Scenarios (selected case); FY29–31 fade at row 43 | U10: 6 · All three — sticky coverage + aftermarket + carriers
B11: y/y growth | C11: % | D11: -- | E11: =E10/D10-1 | F11: =F10/E10-1 | G11: =G10/F10-1 | H11: =H10/G10-1 | I11: =I10/H10-1 | J11: =J10/I10-1 | K11: =K10/J10-1 | L11: =L10/K10-1 | M11: =M10/L10-1 | U11: 7 · Bull — premium-response coverage, ASP +6%
B12: Vehicle sales (bought & resold) | C12: $M | D12: 619.2 | E12: 669.9 | F12: 675.8 | G12: 678.3 | H12: 696.7 | I12: =Scenarios!Q127 | J12: =Scenarios!R127 | K12: =J12*(1+$D$44) | L12: =K12*(1+$D$44) | M12: =L12*(1+$D$44) | N12: =IFERROR((M12/H12)^(1/5)-1,"") | P12: FY27–28 from Scenarios (E6 purchased overlay); FY29–31 fade at row 44
B13: y/y growth | C13: % | D13: -- | E13: =E12/D12-1 | F13: =F12/E12-1 | G13: =G12/F12-1 | H13: =H12/G12-1 | I13: =I12/H12-1 | J13: =J12/I12-1 | K13: =K12/J12-1 | L13: =L12/K12-1 | M13: =M12/L12-1
B14: check (service + vehicle sales = total reported revenue) | C14: $M | D14: =D10+D12-D6 | E14: =E10+E12-E6 | F14: =F10+F12-F6 | G14: =G10+G12-G6 | H14: =H10+H12-H6
B16: Unit build
B17: FY2026 global units | C17: 000s | H17: 4000 | P17: <- As an anchor for forecasts. Copart only discloses % change in its units sold. FY2026, Copart said "over 4million"-> assuming 4m units for FY2026
B18: FY2026 unit mix: US insurance / US non-insurance / International | C18: % | F18: 0.65 | G18: 0.17 | H18: =1-F18-G18 | P18: Estimates
B20: Unit growth by channel
B21: US insurance units, y/y | C21: % | G21: 0.042 | H21: -0.08 | I21: =Scenarios!Q128/Scenarios!P128-1 | J21: =Scenarios!R128/Scenarios!Q128-1 | K21: =$D$45 | L21: =$D$45 | M21: =$D$45 | P21: FY27–28 from Scenarios (E2 pool × E3 share × E4); FY29–31 fade at row 45
B22: US non-insurance units, y/y | C22: % | G22: 0.028 | H22: -0.039 | I22: ='Volume Build'!I33 | J22: ='Volume Build'!J33 | K22: ='Volume Build'!K33 | L22: ='Volume Build'!L33 | M22: ='Volume Build'!M33 | P22: Forecasts link to volume build
B23: International units, y/y | C23: % | G23: 0.081 | H23: 0.037 | I23: ='Volume Build'!I34 | J23: ='Volume Build'!J34 | K23: ='Volume Build'!K34 | L23: ='Volume Build'!L34 | M23: ='Volume Build'!M34 | P23: Owner-entered from Copart calls (international units y/y)
B25: Units by channel
B26: US insurance units | C26: 000s | F26: =G26/(1+G21) | G26: =H26/(1+H21) | H26: =$H$17*$F$18 | I26: =H26*(1+I21) | J26: =I26*(1+J21) | K26: =J26*(1+K21) | L26: =K26*(1+L21) | M26: =L26*(1+M21) | P26: Starting from FY2026 anchor (4m), work backwards using disclosed growth rates to reconstruct FY25 and FY24, and forecast forward
B27: US non-insurance units (dealer, BluCar, Direct, charity) | C27: 000s | F27: =G27/(1+G22) | G27: =H27/(1+H22) | H27: =$H$17*$G$18 | I27: =H27*(1+I22) | J27: =I27*(1+J22) | K27: =J27*(1+K22) | L27: =K27*(1+L22) | M27: =L27*(1+M22)
B28: International units | C28: 000s | F28: =G28/(1+G23) | G28: =H28/(1+H23) | H28: =$H$17*$H$18 | I28: =H28*(1+I23) | J28: =I28*(1+J23) | K28: =J28*(1+K23) | L28: =K28*(1+L23) | M28: =L28*(1+M23)
B29: Global fee units | C29: 000s | D29: =IF(COUNT(D26:D28)=3,SUM(D26:D28),"") | E29: =IF(COUNT(E26:E28)=3,SUM(E26:E28),"") | F29: =SUM(F26:F28) | G29: =SUM(G26:G28) | H29: =SUM(H26:H28) | I29: =SUM(I26:I28) | J29: =SUM(J26:J28) | K29: =SUM(K26:K28) | L29: =SUM(L26:L28) | M29: =SUM(M26:M28) | N29: =IFERROR((M29/H29)^(1/5)-1,"")
B30: y/y growth | C30: % | D30: -- | E30: =IFERROR(E29/D29-1,"") | F30: =IFERROR(F29/E29-1,"") | G30: =G29/F29-1 | H30: =H29/G29-1 | I30: =I29/H29-1 | J30: =J29/I29-1 | K30: =K29/J29-1 | L30: =L29/K29-1 | M30: =M29/L29-1
B32: Revenue per unit (RPU)
B33: Service revenue per fee unit | C33: $ | D33: =IFERROR(D10*1000/D29,"") | E33: =IFERROR(E10*1000/E29,"") | F33: =F10*1000/F29 | G33: =G10*1000/G29 | H33: =H10*1000/H29 | I33: =I10*1000/I29 | J33: =J10*1000/J29 | K33: =K10*1000/K29 | L33: =L10*1000/L29 | M33: =M10*1000/M29 | N33: =(M33/H33)^(1/5)-1 | P33: Implied: service revenue ÷ global fee units (no longer a driver)
B34: RPU growth, y/y | C34: % | E34: =IFERROR(E33/D33-1,"") | F34: =IFERROR(F33/E33-1,"") | G34: =G33/F33-1 | H34: =H33/G33-1 | I34: =I33/H33-1 | J34: =J33/I33-1 | K34: =K33/J33-1 | L34: =L33/K33-1 | M34: =M33/L33-1 | P34: Implied from row 33
B36: Disclosed revenue-per-unit and ASP growth (for checking purposes) | P36: Disclosed by Copart (calls, 8-Ks); owner-entered in v1
B37: Global revenue per unit, y/y (disclosed) | C37: % | H37: 0.057 | P37: Disclosed by Copart (calls); owner-entered in v1
B38: Global ASP, y/y (disclosed) | C38: % | H38: 0.055 | P38: Disclosed by Copart (calls); owner-entered in v1
B39: International revenue, $M (disclosed) | C39: $M | G39: 791.9 | H39: 858.8 | P39: 8-K segment revenue; owner-entered in v1 (see D Reported geography table)
B40: US revenue, $M (disclosed) | C40: $M | G40: 3855.1 | H40: 3807.4 | P40: 8-K segment revenue; owner-entered in v1 (see D Reported geography table)
B42: Beyond the engine horizon (FY29–31): fade inputs
B43: Service revenue growth, FY29–31 | C43: % | D43: 0.03 | P43: ASSUMED: roughly the FY28 engine growth; the engines stop at FY28
B44: Vehicle-sales revenue growth, FY29–31 | C44: % | D44: 0 | P44: ASSUMED flat
B45: US insurance unit growth, FY29–31 | C45: % | D45: 0.01 | P45: ASSUMED
B47: Delta Δ to Street and to the engine (FY27E service revenue, legacy, ex-ACV)
...

Sheet 3SM
B1: Copart, Inc. — Three-statement model (3SM), FY2022A–FY2031E ($M; fiscal year ends 31 July)
B2: Revenue = RPM (selected case). Facility operations = fee units × cost per unit. Other lines: Barclays 11 Sep 2026 where published, else FY2026 actual ratio held. Blue = input, black = formula, green = link, red = selector. History = PitchBook / 10-K.
C4: Units | D4: Historicals | I4: Projected | O4: Notes / sources
B5: Income statement | D5: FY2022A | E5: FY2023A | F5: FY2024A | G5: FY2025A | H5: FY2026A | I5: FY2027E | J5: FY2028E | K5: FY2029E | L5: FY2030E | M5: FY2031E
B6: Service revenue | C6: $M | D6: =RPM!D10 | E6: =RPM!E10 | F6: =RPM!F10 | G6: =RPM!G10 | H6: =RPM!H10 | I6: =RPM!I10 | J6: =RPM!J10 | K6: =RPM!K10 | ... M6: =RPM!M10 | O6: RPM row 10: FY24–26 per 10-K; FY27–28 from the engines (selected case, RPM D3); FY29–31 fade (RPM row 43)
B7: Vehicle sales | C7: $M | D7: =RPM!D12 | E7: =RPM!E12 | F7: =RPM!F12 | G7: =RPM!G12 | H7: =RPM!H12 | I7: =RPM!I12 | J7: =RPM!J12 | K7: =RPM!K12 | ... M7: =RPM!M12 | O7: RPM row 12
B8: Total revenue | C8: $M | D8: =RPM!D6 | E8: =RPM!E6 | F8: =RPM!F6 | G8: =RPM!G6 | H8: =RPM!H6 | I8: =RPM!I6 | J8: =RPM!J6 | K8: =RPM!K6 | ... M8: =RPM!M6 | O8: RPM row 6 (history = PitchBook total revenue)
B9: y/y growth | C9: % | D9: – | E9: =IF(D8=0,0,E8/D8-1) | F9: =IF(E8=0,0,F8/E8-1) | G9: =IF(F8=0,0,G8/F8-1) | H9: =IF(G8=0,0,H8/G8-1) | I9: =IF(H8=0,0,I8/H8-1) | J9: =IF(I8=0,0,J8/I8-1) | K9: =IF(J8=0,0,K8/J8-1) | L9: =IF(K8=0,0,L8/K8-1) | M9: =IF(L8=0,0,M8/L8-1)
B10: Facility operations (incl. yard D&A) | C10: $M | D10: ='PB IS (Annual)'!Q19/1000-D11 | E10: ='PB IS (Annual)'!P19/1000-E11 | F10: ='PB IS (Annual)'!O19/1000-F11 | G10: ='PB IS (Annual)'!N19/1000-G11 | H10: ='PB IS (Annual)'!M19/1000-H11 | I10: =I124*I125/1000 | J10: =J124*J125/1000 | K10: =K124*K125/1000 | L10: =L124*L125/1000 | M10: =M124*M125/1000 | O10: History: PitchBook total cost of revenue − cost of vehicle sales (10-K). Projection: global fee units (RPM row 29) × facility cost per unit (schedule 1) — the volume-driven margin lever
B11: Cost of vehicle sales | C11: $M | D11: ='D 10-K FY26'!E56 | E11: ='D 10-K FY26'!D56 | F11: ='D 10-K FY26'!E39 | G11: ='D 10-K FY26'!D39 | H11: ='D 10-K FY26'!C39 | I11: =I7*I127 | J11: =J7*J127 | K11: =K7*K127 | L11: =L7*L127 | M11: =M7*M127 | O11: History: 10-K income statements (FY2026 and FY2024 filings, D 10-K FY26). Projection: vehicle sales × FY2026 ratio (schedule 1)
B12: Gross profit | C12: $M | D12: =D8-D10-D11 | E12: =E8-E10-E11 | F12: =F8-F10-F11 | G12: =G8-G10-G11 | H12: =H8-H10-H11 | I12: =I8-I10-I11 | J12: =J8-J10-J11 | K12: =K8-K10-K11 | ... M12: =M8-M10-M11
B13: Gross margin | C13: % | D13: =IF(D8=0,0,D12/D8) | E13: =IF(E8=0,0,E12/E8) | F13: =IF(F8=0,0,F12/F8) | G13: =IF(G8=0,0,G12/G8) | H13: =IF(H8=0,0,H12/H8) | I13: =IF(I8=0,0,I12/I8) | J13: =IF(J8=0,0,J12/J8) | K13: =IF(K8=0,0,K12/K8) | ... M13: =IF(M8=0,0,M12/M8)
B14: General and administrative (incl. D&A, SBC) | C14: $M | D14: ='PB IS (Annual)'!Q31/1000 | E14: ='PB IS (Annual)'!P31/1000 | F14: ='PB IS (Annual)'!O31/1000 | G14: ='PB IS (Annual)'!N31/1000 | H14: ='PB IS (Annual)'!M31/1000 | I14: =I8*I128 | J14: =J8*J128 | K14: =K8*K128 | L14: =L8*L128 | M14: =M8*M128 | O14: History: PitchBook total operating expenses = 10-K G&A. Projection: revenue × Barclays-implied G&A ratio (schedule 1)
B15: Operating income (EBIT) | C15: $M | D15: =D12-D14 | E15: =E12-E14 | F15: =F12-F14 | G15: =G12-G14 | H15: =H12-H14 | I15: =I12-I14 | J15: =J12-J14 | K15: =K12-K14 | ... M15: =M12-M14
B16: Operating margin | C16: % | D16: =IF(D8=0,0,D15/D8) | E16: =IF(E8=0,0,E15/E8) | F16: =IF(F8=0,0,F15/F8) | G16: =IF(G8=0,0,G15/G8) | H16: =IF(H8=0,0,H15/H8) | I16: =IF(I8=0,0,I15/I8) | J16: =IF(J8=0,0,J15/J8) | K16: =IF(K8=0,0,K15/K8) | ... M16: =IF(M8=0,0,M15/M8)
B17: Depreciation and amortization | C17: $M | D17: ='PB IS (Annual)'!Q93/1000 | E17: ='PB IS (Annual)'!P93/1000 | F17: ='PB IS (Annual)'!O93/1000 | G17: ='PB IS (Annual)'!N93/1000 | H17: ='PB IS (Annual)'!M93/1000 | I17: =I133 | J17: =J133 | K17: =K133 | L17: =L133 | M17: =M133 | O17: History: PitchBook supplemental D&A (10-K). Projection: schedule 2 (Barclays EBITDA − EBIT for FY27–29)
B18: Adjusted EBITDA (EBIT + D&A; Barclays definition) | C18: $M | D18: =D15+D17 | E18: =E15+E17 | F18: =F15+F17 | G18: =G15+G17 | H18: =H15+H17 | I18: =I15+I17 | J18: =J15+J17 | K18: =K15+K17 | ... M18: =M15+M17 | O18: Barclays' "EBITDA (adj)" = EBIT + D&A (FY26: 1,882); no SBC add-back
B19: Adjusted EBITDA margin | C19: % | D19: =IF(D8=0,0,D18/D8) | E19: =IF(E8=0,0,E18/E8) | F19: =IF(F8=0,0,F18/F8) | G19: =IF(G8=0,0,G18/G8) | H19: =IF(H8=0,0,H18/H8) | I19: =IF(I8=0,0,I18/I8) | J19: =IF(J8=0,0,J18/J8) | K19: =IF(K8=0,0,K18/K8) | ... M19: =IF(M8=0,0,M18/M8)
B20: Interest and other income, net | C20: $M | D20: ='PB IS (Annual)'!Q48/1000 | E20: ='PB IS (Annual)'!P48/1000 | F20: ='PB IS (Annual)'!O48/1000 | G20: ='PB IS (Annual)'!N48/1000 | H20: ='PB IS (Annual)'!M48/1000 | I20: =I139 | J20: =J139 | K20: =K139 | L20: =L139 | M20: =M139 | O20: History: PitchBook total non-operating income (interest income, net + other). Projection: yield × opening cash & HTM (schedule 3)
B21: Pre-tax income | C21: $M | D21: =D15+D20 | E21: =E15+E20 | F21: =F15+F20 | G21: =G15+G20 | H21: =H15+H20 | I21: =I15+I20 | J21: =J15+J20 | K21: =K15+K20 | ... M21: =M15+M20
B22: Income tax expense | C22: $M | D22: ='PB IS (Annual)'!Q50/1000 | E22: ='PB IS (Annual)'!P50/1000 | F22: ='PB IS (Annual)'!O50/1000 | G22: ='PB IS (Annual)'!N50/1000 | H22: ='PB IS (Annual)'!M50/1000 | I22: =I21*I23 | J22: =J21*J23 | K22: =K21*K23 | L22: =L21*L23 | M22: =M21*M23 | O22: Projection: pre-tax × structural rate
B23: Effective tax rate | C23: % | D23: =IF(D21=0,0,D22/D21) | E23: =IF(E21=0,0,E22/E21) | F23: =IF(F21=0,0,F22/F21) | G23: =IF(G21=0,0,G22/G21) | H23: =IF(H21=0,0,H22/H21) | I23: ='WACC, Tax, and Reverse DCF'!$N$39 | J23: ='WACC, Tax, and Reverse DCF'!$N$39 | K23: ='WACC, Tax, and Reverse DCF'!$N$39 | L23: ='WACC, Tax, and Reverse DCF'!$N$39 | M23: ='WACC, Tax, and Reverse DCF'!$N$39 | O23: FY27+: structural rate from the tax build (Reverse DCF S29–S33: 21% statutory + state − FDII − option benefit); Barclays-implied 20.3% in schedule 7
B24: Net income (consolidated) | C24: $M | D24: =D21-D22 | E24: =E21-E22 | F24: =F21-F22 | G24: =G21-G22 | H24: =H21-H22 | I24: =I21-I22 | J24: =J21-J22 | K24: =K21-K22 | ... M24: =M21-M22
B25: Net (income) loss attributable to noncontrolling interest | C25: $M | D25: ='PB IS (Annual)'!Q56/1000-'PB IS (Annual)'!Q54/1000 | E25: ='PB IS (Annual)'!P56/1000-'PB IS (Annual)'!P54/1000 | F25: ='PB IS (Annual)'!O56/1000-'PB IS (Annual)'!O54/1000 | G25: ='PB IS (Annual)'!N56/1000-'PB IS (Annual)'!N54/1000 | H25: ='PB IS (Annual)'!M56/1000-'PB IS (Annual)'!M54/1000 | I25: 0 | J25: 0 | K25: 0 | L25: 0 | M25: 0 | O25: History: NI to Copart − consolidated NI (positive = NCI loss added back). Projection: ASSUMED 0 (Barclays ignores NCI; FY26 was +3.9)
B26: Net income attributable to Copart | C26: $M | D26: =D24+D25 | E26: =E24+E25 | F26: =F24+F25 | G26: =G24+G25 | H26: =H24+H25 | I26: =I24+I25 | J26: =J24+J25 | K26: =K24+K25 | ... M26: =M24+M25
B27: Diluted weighted-average shares | C27: M | D27: ='PB IS (Annual)'!Q68/1000000 | E27: ='PB IS (Annual)'!P68/1000000 | F27: ='PB IS (Annual)'!O68/1000000 | G27: ='PB IS (Annual)'!N68/1000000 | H27: ='PB IS (Annual)'!M68/1000000 | I27: =I151 | J27: =J151 | K27: =K151 | L27: =L151 | M27: =M151 | O27: Projection: schedule 5
B28: Diluted EPS | C28: $ | D28: =IF(D27=0,0,D26/D27) | E28: =IF(E27=0,0,E26/E27) | F28: =IF(F27=0,0,F26/F27) | G28: =IF(G27=0,0,G26/G27) | H28: =IF(H27=0,0,H26/H27) | I28: =IF(I27=0,0,I26/I27) | J28: =IF(J27=0,0,J26/J27) | K28: =IF(K27=0,0,K26/K27) | ... M28: =IF(M27=0,0,M26/M27)
B29: y/y growth | C29: % | D29: – | E29: =IF(D28=0,0,E28/D28-1) | F29: =IF(E28=0,0,F28/E28-1) | G29: =IF(F28=0,0,G28/F28-1) | H29: =IF(G28=0,0,H28/G28-1) | I29: =IF(H28=0,0,I28/H28-1) | J29: =IF(I28=0,0,J28/I28-1) | K29: =IF(J28=0,0,K28/J28-1) | L29: =IF(K28=0,0,L28/K28-1) | M29: =IF(L28=0,0,M28/L28-1)
B30: Barclays parity — income statement (Barclays publishes FY2026A–FY2029E only; Δ = 3SM − Barclays)
B31: Barclays revenue | C31: $M | D31: – | E31: – | F31: – | G31: – | H31: ='D Barclays'!D5 | I31: ='D Barclays'!E5 | J31: ='D Barclays'!F5 | K31: ='D Barclays'!G5 | L31: – | M31: – | O31: D Barclays row 5
B32: Δ revenue | C32: $M | D32: – | E32: – | F32: – | G32: – | H32: =H8-H31 | I32: =I8-I31 | J32: =J8-J31 | K32: =K8-K31 | L32: – | M32: –
B33: Barclays adjusted EBITDA | C33: $M | D33: – | E33: – | F33: – | G33: – | H33: ='D Barclays'!D6 | I33: ='D Barclays'!E6 | J33: ='D Barclays'!F6 | K33: ='D Barclays'!G6 | L33: – | M33: –
B34: Δ adjusted EBITDA | C34: $M | D34: – | E34: – | F34: – | G34: – | H34: =H18-H33 | I34: =I18-I33 | J34: =J18-J33 | K34: =K18-K33 | L34: – | M34: –
B35: Barclays EBIT | C35: $M | D35: – | E35: – | F35: – | G35: – | H35: ='D Barclays'!D7 | I35: ='D Barclays'!E7 | J35: ='D Barclays'!F7 | K35: ='D Barclays'!G7 | L35: – | M35: –
B36: Δ EBIT | C36: $M | D36: – | E36: – | F36: – | G36: – | H36: =H15-H35 | I36: =I15-I35 | J36: =J15-J35 | K36: =K15-K35 | L36: – | M36: –
B37: Barclays pre-tax income | C37: $M | D37: – | E37: – | F37: – | G37: – | H37: ='D Barclays'!D8 | I37: ='D Barclays'!E8 | J37: ='D Barclays'!F8 | K37: ='D Barclays'!G8 | L37: – | M37: –
B38: Δ pre-tax income | C38: $M | D38: – | E38: – | F38: – | G38: – | H38: =H21-H37 | I38: =I21-I37 | J38: =J21-J37 | K38: =K21-K37 | L38: – | M38: –
B39: Barclays net income | C39: $M | D39: – | E39: – | F39: – | G39: – | H39: ='D Barclays'!D9 | I39: ='D Barclays'!E9 | J39: ='D Barclays'!F9 | K39: ='D Barclays'!G9 | L39: – | M39: –
B40: Δ net income | C40: $M | D40: – | E40: – | F40: – | G40: – | H40: =H26-H39 | I40: =I26-I39 | J40: =J26-J39 | K40: =K26-K39 | L40: – | M40: –
B41: Barclays diluted EPS | C41: $ | D41: – | E41: – | F41: – | G41: – | H41: ='D Barclays'!D10 | I41: ='D Barclays'!E10 | J41: ='D Barclays'!F10 | K41: ='D Barclays'!G10 | L41: – | M41: –
...

Sheet DCF
B1: Copart, Inc. — Discounted Cash Flow
B2: Fiscal year ends 31 July. $M unless noted. Historicals link to PitchBook tabs; revenue links to RPM.
C4: Units | D4: Historicals | I4: Projected
B5: Income statement | D5: FY2022A | E5: FY2023A | F5: FY2024A | G5: FY2025A | H5: FY2026A | I5: FY2027E | J5: FY2028E | K5: FY2029E | L5: FY2030E | M5: FY2031E | N5: FY26–31 CAGR
B6: Revenue | C6: $M | D6: =RPM!D6 | E6: =RPM!E6 | F6: =RPM!F6 | G6: =RPM!G6 | H6: =RPM!H6 | I6: =RPM!I6 | J6: =RPM!J6 | K6: =RPM!K6 | ... M6: =RPM!M6 | N6: =(M6/H6)^(1/5)-1
B7: y/y growth | C7: % | D7: -- | E7: =E6/D6-1 | F7: =F6/E6-1 | G7: =G6/F6-1 | H7: =H6/G6-1 | I7: =I6/H6-1 | J7: =J6/I6-1 | K7: =K6/J6-1 | L7: =L6/K6-1 | M7: =M6/L6-1
B8: of which service revenue | C8: $M | D8: =RPM!D10 | E8: =RPM!E10 | F8: =RPM!F10 | G8: =RPM!G10 | H8: =RPM!H10 | I8: =RPM!I10 | J8: =RPM!J10 | K8: =RPM!K10 | ... M8: =RPM!M10 | P8: Copart doesn't own car
B9: of which vehicle sales | C9: $M | D9: =RPM!D12 | E9: =RPM!E12 | F9: =RPM!F12 | G9: =RPM!G12 | H9: =RPM!H12 | I9: =RPM!I12 | J9: =RPM!J12 | K9: =RPM!K12 | ... M9: =RPM!M12 | P9: Copart buys & resells car
B11: Global fee units | C11: 000s | F11: =RPM!F29 | G11: =RPM!G29 | H11: =RPM!H29 | I11: =RPM!I29 | J11: =RPM!J29 | K11: =RPM!K29 | L11: =RPM!L29 | M11: =RPM!M29 | P11: # of times Copart sold through auctions
B13: Facility operations (cost of service revenue, incl. yard D&A) | C13: $M | D13: 1275.5 | E13: 1462.6 | F13: 1653.8 | G13: 1944.3 | H13: 1965.9 | I13: =I11*I14/1000 | J13: =J11*J14/1000 | K13: =K11*K14/1000 | L13: =L11*L14/1000 | M13: =M11*M14/1000
B14: Facility cost per fee unit | C14: $ | F14: =F13*1000/F11 | G14: =G13*1000/G11 | H14: =H13*1000/H11 | I14: =H14*(1+I15) | J14: =I14*(1+J15) | K14: =J14*(1+K15) | L14: =K14*(1+L15) | M14: =L14*(1+M15) | P14: facility ops / # of cars. If Copart handles fewer cars but yard costs stay the same, cost/car rises
B15: Facility cost per unit, y/y | C15: % | G15: =G14/F14-1 | H15: =H14/G14-1 | I15: 0.045 | J15: 0.025 | K15: 0.02 | L15: 0.02 | M15: 0.02
B16: Cost of vehicle sales | C16: $M | D16: 619.2 | E16: 669.9 | F16: 675.8 | G16: 603 | H16: 616.5 | I16: =I9*I17 | J16: =J9*J17 | K16: =K9*K17 | L16: =L9*L17 | M16: =M9*M17
B17: as % of vehicle sales | C17: % | D17: =D16/D9 | E17: =E16/E9 | F17: =F16/F9 | G17: =G16/G9 | H17: =H16/H9 | I17: 0.885 | J17: 0.885 | K17: 0.885 | L17: 0.885 | M17: 0.885
B18: Gross profit | C18: $M | D18: =D6-D13-D16 | E18: =E6-E13-E16 | F18: =F6-F13-F16 | G18: =G6-G13-G16 | H18: =H6-H13-H16 | I18: =I6-I13-I16 | J18: =J6-J13-J16 | K18: =K6-K13-K16 | ... M18: =M6-M13-M16 | N18: =(M18/H18)^(1/5)-1
B19: Gross margin | C19: % | D19: =D18/D6 | E19: =E18/E6 | F19: =F18/F6 | G19: =G18/G6 | H19: =H18/H6 | I19: =I18/I6 | J19: =J18/J6 | K19: =K18/K6 | ... M19: =M18/M6
B21: General & administrative (incl. D&A, SBC) | C21: $M | D21: ='PB IS (Annual)'!Q31/1000 | E21: ='PB IS (Annual)'!P31/1000 | F21: ='PB IS (Annual)'!O31/1000 | G21: ='PB IS (Annual)'!N31/1000 | H21: ='PB IS (Annual)'!M31/1000 | I21: =H21*(1+I22) | J21: =I21*(1+J22) | K21: =J21*(1+K22) | L21: =K21*(1+L22) | M21: =L21*(1+M22)
B22: G&A growth, y/y | C22: % | E22: =E21/D21-1 | F22: =F21/E21-1 | G22: =G21/F21-1 | H22: =H21/G21-1 | I22: 0.07 | J22: 0.05 | K22: 0.04 | L22: 0.04 | M22: 0.04
B23: as % of revenue | C23: % | D23: =D21/D6 | E23: =E21/E6 | F23: =F21/F6 | G23: =G21/G6 | H23: =H21/H6 | I23: =I21/I6 | J23: =J21/J6 | K23: =K21/K6 | ... M23: =M21/M6
B24: Operating income (EBIT) | C24: $M | D24: =D18-D21 | E24: =E18-E21 | F24: =F18-F21 | G24: =G18-G21 | H24: =H18-H21 | I24: =I18-I21 | J24: =J18-J21 | K24: =K18-K21 | ... M24: =M18-M21 | N24: =(M24/H24)^(1/5)-1
B25: Operating margin | C25: % | D25: =D24/D6 | E25: =E24/E6 | F25: =F24/F6 | G25: =G24/G6 | H25: =H24/H6 | I25: =I24/I6 | J25: =J24/J6 | K25: =K24/K6 | ... M25: =M24/M6
B26: y/y growth | C26: % | D26: -- | E26: =E24/D24-1 | F26: =F24/E24-1 | G26: =G24/F24-1 | H26: =H24/G24-1 | I26: =I24/H24-1 | J26: =J24/I24-1 | K26: =K24/J24-1 | L26: =L24/K24-1 | M26: =M24/L24-1
B27: check vs pitchBook operating profit | C27: $M | D27: =D24-'PB IS (Annual)'!Q32/1000 | E27: =E24-'PB IS (Annual)'!P32/1000 | F27: =F24-'PB IS (Annual)'!O32/1000 | G27: =G24-'PB IS (Annual)'!N32/1000 | H27: =H24-'PB IS (Annual)'!M32/1000
B29: Depreciation & amortization | C29: $M | D29: ='PB CF (Annual)'!Q18/1000 | E29: ='PB CF (Annual)'!P18/1000 | F29: ='PB CF (Annual)'!O18/1000 | G29: ='PB CF (Annual)'!N18/1000 | H29: ='PB CF (Annual)'!M18/1000 | I29: ='3SM'!I17 | J29: ='3SM'!J17 | K29: ='3SM'!K17 | L29: ='3SM'!L17 | M29: ='3SM'!M17 | P29: From the 3SM row 17 (Barclays D&A FY27–29; FY30–31 at the FY29 rate); row 30 is now the implied %
B30: as % of revenue | C30: % | D30: =D29/D6 | E30: =E29/E6 | F30: =F29/F6 | G30: =G29/G6 | H30: =H29/H6 | I30: =I29/I6 | J30: =J29/J6 | K30: =K29/K6 | ... M30: =M29/M6
B31: EBITDA | C31: $M | D31: =D24+D29 | E31: =E24+E29 | F31: =F24+F29 | G31: =G24+G29 | H31: =H24+H29 | I31: =I24+I29 | J31: =J24+J29 | K31: =K24+K29 | ... M31: =M24+M29 | N31: =(M31/H31)^(1/5)-1
B32: EBITDA margin | C32: % | D32: =D31/D6 | E32: =E31/E6 | F32: =F31/F6 | G32: =G31/G6 | H32: =H31/H6 | I32: =I31/I6 | J32: =J31/J6 | K32: =K31/K6 | ... M32: =M31/M6
B34: Interest & other income | C34: $M | D34: ='PB IS (Annual)'!Q48/1000 | E34: ='PB IS (Annual)'!P48/1000 | F34: ='PB IS (Annual)'!O48/1000 | G34: ='PB IS (Annual)'!N48/1000 | H34: ='PB IS (Annual)'!M48/1000 | I34: =H72*I35 | J34: =I72*J35 | K34: =J72*K35 | L34: =K72*L35 | M34: =L72*M35 | P34: Yield on Copart's $4.5b in Treasury bills
B35: Yield on cash & HTM securities | C35: % | I35: 0.036 | J35: 0.034 | K35: 0.033 | L35: 0.033 | M35: 0.033
B36: Pre-tax income | C36: $M | D36: =D24+D34 | E36: =E24+E34 | F36: =F24+F34 | G36: =G24+G34 | H36: =H24+H34 | I36: =I24+I34 | J36: =J24+J34 | K36: =K24+K34 | ... M36: =M24+M34
B37: Income tax | C37: $M | D37: ='PB IS (Annual)'!Q50/1000 | E37: ='PB IS (Annual)'!P50/1000 | F37: ='PB IS (Annual)'!O50/1000 | G37: ='PB IS (Annual)'!N50/1000 | H37: ='PB IS (Annual)'!M50/1000 | I37: =I36*I38 | J37: =J36*J38 | K37: =K36*K38 | L37: =L36*L38 | M37: =M36*M38
B38: Effective tax rate | C38: % | D38: =D37/D36 | E38: =E37/E36 | F38: =F37/F36 | G38: =G37/G36 | H38: =H37/H36 | I38: ='WACC, Tax, and Reverse DCF'!$N$39 | J38: ='WACC, Tax, and Reverse DCF'!$N$39 | K38: ='WACC, Tax, and Reverse DCF'!$N$39 | L38: ='WACC, Tax, and Reverse DCF'!$N$39 | M38: ='WACC, Tax, and Reverse DCF'!$N$39 | P38: FY27+ = structural effective rate from the tax build (Reverse DCF R28–R36)
B39: Net income | C39: $M | D39: ='PB IS (Annual)'!Q56/1000 | E39: ='PB IS (Annual)'!P56/1000 | F39: ='PB IS (Annual)'!O56/1000 | G39: ='PB IS (Annual)'!N56/1000 | H39: ='PB IS (Annual)'!M56/1000 | I39: =I36-I37 | J39: =J36-J37 | K39: =K36-K37 | L39: =L36-L37 | M39: =M36-M37 | N39: =(M39/H39)^(1/5)-1
B40: Diluted shares | C40: M | D40: ='PB IS (Annual)'!Q68/1000000 | E40: ='PB IS (Annual)'!P68/1000000 | F40: ='PB IS (Annual)'!O68/1000000 | G40: ='PB IS (Annual)'!N68/1000000 | H40: ='PB IS (Annual)'!M68/1000000 | I40: =H40-I69/I70 | J40: =I40-J69/J70 | K40: =J40-K69/K70 | L40: =K40-L69/L70 | M40: =L40-M69/M70
B41: Diluted EPS | C41: $ | D41: =D39/D40 | E41: =E39/E40 | F41: =F39/F40 | G41: =G39/G40 | H41: =H39/H40 | I41: =I39/I40 | J41: =J39/J40 | K41: =K39/K40 | ... M41: =M39/M40 | N41: =(M41/H41)^(1/5)-1
B42: y/y growth | C42: % | D42: -- | E42: =E41/D41-1 | F42: =F41/E41-1 | G42: =G41/F41-1 | H42: =H41/G41-1 | I42: =I41/H41-1 | J42: =J41/I41-1 | K42: =K41/J41-1 | L42: =L41/K41-1 | M42: =M41/L41-1
B44: Street EPS
B45: Barclays (UW, $25) -- 11 Sep 2026 | C45: $ | H45: 1.55 | I45: 1.56 | J45: 1.64 | K45: 1.72
B46: Model vs. Barclays | C46: % | I46: =I41/I45-1 | J46: =J41/J45-1
B48: Unlevered free cash flow
...

Sheet WACC, Tax, and Reverse DCF
B1: Copart, Inc. — Reverse DCF
B4: Market-implied case
B5: Implied flat revenue growth, FY27–FY28 (solved so the implied price in H51 equals the current price in H52 at the exit multiple in H36) | H5: 0.158089
C8: Units | D8: Historicals | I8: Projected
B9: Income statement | D9: FY2022A | E9: FY2023A | F9: FY2024A | G9: FY2025A | H9: FY2026A | I9: FY2027E | J9: FY2028E | K9: CAGR
B10: Revenue | C10: $M | D10: ='PB IS (Annual)'!Q14/1000 | E10: ='PB IS (Annual)'!P14/1000 | F10: ='PB IS (Annual)'!O14/1000 | G10: ='PB IS (Annual)'!N14/1000 | H10: ='PB IS (Annual)'!M14/1000 | I10: =H10*(1+$H$5) | J10: =I10*(1+$H$5) | K10: =_xlfn.RRI(3, H10, J10) | M10: WACC build | N10: Value | O10: Label
B11: y/y growth | C11: % | D11: -- | E11: =E10/D10-1 | F11: =F10/E10-1 | G11: =G10/F10-1 | H11: =H10/G10-1 | I11: =I10/H10-1 | J11: =J10/I10-1 | K11: – | M11: Current share price | N11: =Cover!$D$6 | O11: – | P11: – | Q11: – | R11: Cover D6 — the one typed price in the workbook
M12: Fully diluted shares, mn | N12: =Cover!$D$15 | O12: – | P12: – | Q12: – | R12: Cover D15: basic + treasury-method options + RSUs (10-K Note 12)
B13: EBITDA | C13: $M | D13: =DCF!D31 | E13: =DCF!E31 | F13: =DCF!F31 | G13: =DCF!G31 | H13: =DCF!H31 | I13: =I10*I14 | J13: =J10*J14 | K13: =_xlfn.RRI(3, H13, J13) | M13: Market value of equity ($m) | N13: =Cover!$D$10 | O13: – | P13: – | Q13: –
B14: EBITDA margin | C14: % | D14: =D13/D10 | E14: =E13/E10 | F14: =F13/F10 | G14: =G13/G10 | H14: =H13/H10 | I14: 0.408 | J14: 0.412 | K14: – | M14: Debt: lease liabilities ($m), no funded debt | N14: =Cover!$D$13 | O14: – | P14: – | Q14: – | R14: Cover D13 ← 3SM balance sheet; revolver undrawn
B15: y/y growth | C15: % | D15: -- | E15: =E13/D13-1 | F15: =F13/E13-1 | G15: =G13/F13-1 | H15: =H13/G13-1 | I15: =I13/H13-1 | J15: =J13/I13-1 | K15: – | M15: Weight of equity / weight of debt | N15: =N13/(N13+N14) | O15: =N14/(N13+N14) | P15: – | Q15: –
B17: D&A | C17: $M | D17: =DCF!D29 | E17: =DCF!E29 | F17: =DCF!F29 | G17: =DCF!G29 | H17: =DCF!H29 | I17: 226 | J17: 234 | K17: – | M17: Risk-free rate (10-yr US Treasury, 1 Oct 2026) | N17: 0.0524 | O17: VERIFIED | P17: – | Q17: – | R17: Risk-free rate: 10-year US Treasury par yield, 1 Oct 2026. VERIFIED — US Treasury daily par yield curve, raw/discovery_2026-10-02/ust_yield_curve_2026.csv (row 10/01/2026, 10 Yr)
B18: EBIT | C18: $M | D18: =D13-D17 | E18: =E13-E17 | F18: =F13-F17 | G18: =G13-G17 | H18: =H13-H17 | I18: =I13-I17 | J18: =J13-J17 | K18: =_xlfn.RRI(3, H18, J18) | M18: Equity risk premium (Damodaran, Jan 2026) | N18: 0.0446 | O18: VERIFIED | P18: – | Q18: – | R18: Equity risk premium: United States, Damodaran, January 2026. VERIFIED — Damodaran country risk premiums table (Aa1; mature-market 4.23% + 0.23% CRP), raw/discovery_2026-10-02/damodaran_ctryprem.html
B19: y/y growth | C19: % | D19: -- | E19: =E18/D18-1 | F19: =F18/E18-1 | G19: =G18/F18-1 | H19: =H18/G18-1 | I19: =I18/H18-1 | J19: =J18/I18-1 | K19: – | M19: Industry beta (Damodaran, Jan 2026) | N19: Levered | O19: Unlevered | P19: Cash-corrected | Q19: – | R19: Beta (Damodaran, January 2026): levered / unlevered / cash-corrected unlevered. VERIFIED — raw/discovery_2026-10-02/damodaran_betas.html
M20: Business & Consumer Services (155 firms) | N20: 0.89 | O20: 0.77 | P20: 0.81 | Q20: –
B21: Unlevered free cash flow | M21: Retail (Automotive) (34 firms) | N21: 0.94 | O21: 0.7 | P21: 0.71 | Q21: –
B22: EBIT | C22: $M | D22: =D18 | E22: =E18 | F22: =F18 | G22: =G18 | H22: =H18 | I22: =I18 | J22: =J18 | K22: =_xlfn.RRI(3, H22, J22) | M22: Auto Parts (35 firms) | N22: 1.34 | O22: 1.02 | P22: 1.13 | Q22: –
B23: (−) Taxes on EBIT | C23: $M | D23: =-D18*DCF!D38 | E23: =-E18*DCF!E38 | F23: =-F18*DCF!F38 | G23: =-G18*DCF!G38 | H23: =-H18*DCF!H38 | I23: =-I18*DCF!I38 | J23: =-J18*DCF!J38 | K23: – | M23: Transportation (19 firms) | N23: 0.86 | O23: 0.68 | P23: 0.71 | Q23: –
B24: NOPAT | C24: $M | D24: =D22+D23 | E24: =E22+E23 | F24: =F22+F23 | G24: =G22+G23 | H24: =H22+H23 | I24: =I22+I23 | J24: =J22+J23 | K24: =_xlfn.RRI(3, H24, J24) | M24: Total market (5,994 firms) | N24: 0.91 | O24: 0.72 | P24: 0.76 | Q24: –
B25: (+) D&A | C25: $M | D25: =D17 | E25: =E17 | F25: =F17 | G25: =G17 | H25: =H17 | I25: =I17 | J25: =J17 | K25: – | M25: Peer betas, 5-yr monthly: RBA / KAR / ACVA / CVNA | N25: RBA | O25: KAR | P25: ACVA | Q25: CVNA | R25: Peer company betas (5-year monthly): RB Global, OPENLANE, ACV Auctions, Carvana, Copart. NOT OBTAINED — price downloads refused by the only permitted free source's robots file; paste CapIQ or Bloomberg values here (dated) to override the industry beta
B26: (+) Stock-based compensation (DCF % of revenue) | C26: $M | D26: =DCF!D53 | E26: =DCF!E53 | F26: =DCF!F53 | G26: =DCF!G53 | H26: =DCF!H53 | I26: =I10*DCF!I54 | J26: =J10*DCF!J54 | K26: – | M26: Selected unlevered beta (avg of two closest) | N26: =AVERAGE(P20,P21) | O26: ASSUMED | P26: – | Q26: – | R26: Selected unlevered beta (default: average of the two closest industries, cash-corrected). ASSUMED choice of industries; Copart is an auction-services business with retail-automotive exposure
B27: (−) Capital expenditures (DCF % of revenue) | C27: $M | D27: =DCF!D55 | E27: =DCF!E55 | F27: =DCF!F55 | G27: =DCF!G55 | H27: =DCF!H55 | I27: =-I10*DCF!I56 | J27: =-J10*DCF!J56 | K27: – | M27: Relevered beta = βu × (1 + (1 − t) × D/E) | N27: =N26*(1+(1-N39)*N14/N13) | O27: – | P27: – | Q27: –
B28: (−) Increase in NWC (DCF % of Δrevenue) | C28: $M | D28: =DCF!D57 | E28: =DCF!E57 | F28: =DCF!F57 | G28: =DCF!G57 | H28: =DCF!H57 | I28: -83 | J28: -83 | K28: – | M28: Cost of equity (CAPM) | N28: =N17+N27*N18 | O28: – | P28: – | Q28: –
B29: Unlevered free cash flow | C29: $M | D29: =D24+D25+D26+D27+D28 | E29: =E24+E25+E26+E27+E28 | F29: =F24+F25+F26+F27+F28 | G29: =G24+G25+G26+G27+G28 | H29: =H24+H25+H26+H27+H28 | I29: =I24+I25+I26+I27+I28 | J29: =J24+J25+J26+J27+J28 | K29: =_xlfn.RRI(3, H29, J29) | M29: Pre-tax cost of debt (revolver proxy; weight ≈ 0) | N29: 0.0575 | O29: ASSUMED | P29: – | Q29: – | R29: Pre-tax cost of debt (revolver pricing proxy; weight ≈ 0). ASSUMED: 10-K describes the $1,250m unsecured revolver maturing 23 Jan 2031 without the margin; SOFR + 1.0–1.5% proxy
B30: Discount period (DCF) | C30: yrs | D30: – | E30: – | F30: – | G30: – | H30: – | I30: =DCF!I62 | J30: =DCF!J62 | K30: – | M30: After-tax cost of debt | N30: =N29*(1-N39) | O30: – | P30: – | Q30: –
B31: Discount factor (DCF WACC) | C31: x | D31: – | E31: – | F31: – | G31: – | H31: – | I31: =DCF!I63 | J31: =DCF!J63 | K31: – | M31: WACC | N31: =N15*N28+O15*N30 | O31: – | P31: – | Q31: –
B32: PV of UFCF | C32: $M | D32: – | E32: – | F32: – | G32: – | H32: – | I32: =I29*I31 | J32: =J29*J31 | K32: – | M32: Memo: DCF's previous WACC inputs → 8.725% | R32: Memo: DCF's previous inputs — risk-free 4.21%, beta 1.05, ERP 4.30% → 8.725%
B34: Valuation | M34: Effective tax rate build | N34: Value | O34: Label
B35: WACC | D35: – | E35: – | F35: – | G35: – | H35: =N31 | I35: – | J35: – | K35: – | M35: US federal statutory rate | N35: 0.21 | O35: VERIFIED | P35: – | Q35: – | R35: 10-K MD&A
B36: Exit EV / EBITDA multiple (Barclays: 10× on 2026) | D36: – | E36: – | F36: – | G36: – | H36: 10 | I36: – | J36: – | K36: – | M36: (+) State income taxes ÷ pre-tax income | N36: ='D 10-K FY26'!E34/1834.977 | O36: VERIFIED | P36: – | Q36: – | R36: (+) State income taxes: $21.5m ÷ pre-tax income $1,835m. 10-K MD&A Income Taxes; pre-tax income from the income statement
B37: Terminal year EBITDA (FY2028E, market-implied) | D37: – | E37: – | F37: – | G37: – | H37: =J13 | I37: – | J37: – | K37: – | M37: (−) FDII deduction: $46.7m ÷ pre-tax income | N37: ='D 10-K FY26'!C34/1834.977 | O37: VERIFIED | P37: – | Q37: – | R37: 10-K MD&A; set by federal tax law, check the FY27 deduction rate
B38: Terminal value | D38: – | E38: – | F38: – | G38: – | H38: =H36*H37 | I38: – | J38: – | K38: – | M38: (−) Excess option tax benefit ÷ pre-tax income | N38: ='D 10-K FY26'!D34/1834.977 | O38: VERIFIED | P38: – | Q38: – | R38: (−) Excess tax benefit on option exercises: $6.6m (FY25: $36.7m); excluded from the forward rate because it depends on the share price. 10-K MD&A
B39: PV of terminal value | D39: – | E39: – | F39: – | G39: – | H39: =H38*J31 | I39: – | J39: – | K39: – | M39: Structural effective tax rate → DCF, 3SM | N39: =N35+N36+N37 | O39: – | P39: – | Q39: – | R39: Structural effective tax rate (statutory + state − FDII) → DCF tax rows
B40: PV of explicit UFCF (FY27-FY31) | D40: – | E40: – | F40: – | G40: – | H40: =SUM(I32:L32) | I40: – | J40: – | K40: – | M40: Reported effective rate FY2026 / FY2025 | N40: ='D 10-K FY26'!C33 | O40: ='D 10-K FY26'!D33 | P40: – | Q40: –
B41: Enterprise value | D41: – | E41: – | F41: – | G41: – | H41: =H39+H40 | I41: – | J41: – | K41: – | M41: Cash taxes paid ÷ pre-tax income, FY26 / FY25 | N41: ='D 10-K FY26'!C32/1834.977 | O41: ='D 10-K FY26'!D32/1895.581 | P41: – | Q41: – | R41: Cash taxes paid ÷ pre-tax income, FY2026 / FY2025. Supplemental cash flow
M42: Barclays-implied tax rate, FY2027E | N42: =1-'D Barclays'!E9/'D Barclays'!E8 | O42: – | P42: – | Q42: – | R42: Barclays-implied rate FY2027E (1 − adj. net income ÷ adj. pre-tax)
B43: Equity bridge
B44: Enterprise value | D44: – | E44: – | F44: – | G44: – | H44: =H41 | I44: – | J44: – | K44: –
B45: (+) Cash & HTM securities | D45: – | E45: – | F45: – | G45: – | H45: =Cover!D12 | I45: – | J45: – | K45: –
B46: (−) Total debt | D46: – | E46: – | F46: – | G46: – | H46: =-Cover!D13 | I46: – | J46: – | K46: –
...

Sheet RPM ENGINES ----->
B3: RPM ENGINES ----->

Sheet E1 Fleet
B1: E1 Fleet — vehicles on the road by age and body (thousands)
B2: Fleet(a, b, Y) = Births(Y−a, b) × S_b(a ÷ k_b(Y)); k_b(Y) = k_b(2013) × m(Y). Calendar years; feeds E2 by fiscal-quarter weights. Appendix A, Eq. 1–3.
C3: CY | D3: 2019 | E3: 2020 | F3: 2021 | G3: 2022 | H3: 2023 | I3: 2024 | J3: 2025 | K3: 2026 | L3: 2027 | M3: 2028
C4: Units | D4: Historicals | K4: Projected | P4: Notes / sources
B5: A. Births by body (new light vehicles sold in the calendar year) | D5: CY2019 | E5: CY2020 | F5: CY2021 | G5: CY2022 | H5: CY2023 | I5: CY2024 | J5: CY2025 | K5: CY2026 | L5: CY2027 | M5: CY2028
B6: Car | C6: 000s | D6: =INDEX('D Fleet'!$C$5:$C$63,MATCH(D$3,'D Fleet'!$B$5:$B$63,0)) | E6: =INDEX('D Fleet'!$C$5:$C$63,MATCH(E$3,'D Fleet'!$B$5:$B$63,0)) | F6: =INDEX('D Fleet'!$C$5:$C$63,MATCH(F$3,'D Fleet'!$B$5:$B$63,0)) | G6: =INDEX('D Fleet'!$C$5:$C$63,MATCH(G$3,'D Fleet'!$B$5:$B$63,0)) | H6: =INDEX('D Fleet'!$C$5:$C$63,MATCH(H$3,'D Fleet'!$B$5:$B$63,0)) | I6: =INDEX('D Fleet'!$C$5:$C$63,MATCH(I$3,'D Fleet'!$B$5:$B$63,0)) | J6: =INDEX('D Fleet'!$C$5:$C$63,MATCH(J$3,'D Fleet'!$B$5:$B$63,0)) | K6: =INDEX('D Fleet'!$C$5:$C$63,MATCH(K$3,'D Fleet'!$B$5:$B$63,0)) | ... M6: =INDEX('D Fleet'!$C$5:$C$63,MATCH(M$3,'D Fleet'!$B$5:$B$63,0)) | N6: – | O6: – | P6: D Fleet; Ward's/ORNL to 2021, FRED 2022–25 (VERIFIED); SUV/pickup/van split is an EPA composition proxy (ASSUMED) | Q6: – | R6: –
B7: Utility vehicle (SUV) | C7: 000s | D7: =INDEX('D Fleet'!$D$5:$D$63,MATCH(D$3,'D Fleet'!$B$5:$B$63,0)) | E7: =INDEX('D Fleet'!$D$5:$D$63,MATCH(E$3,'D Fleet'!$B$5:$B$63,0)) | F7: =INDEX('D Fleet'!$D$5:$D$63,MATCH(F$3,'D Fleet'!$B$5:$B$63,0)) | G7: =INDEX('D Fleet'!$D$5:$D$63,MATCH(G$3,'D Fleet'!$B$5:$B$63,0)) | H7: =INDEX('D Fleet'!$D$5:$D$63,MATCH(H$3,'D Fleet'!$B$5:$B$63,0)) | I7: =INDEX('D Fleet'!$D$5:$D$63,MATCH(I$3,'D Fleet'!$B$5:$B$63,0)) | J7: =INDEX('D Fleet'!$D$5:$D$63,MATCH(J$3,'D Fleet'!$B$5:$B$63,0)) | K7: =INDEX('D Fleet'!$D$5:$D$63,MATCH(K$3,'D Fleet'!$B$5:$B$63,0)) | ... M7: =INDEX('D Fleet'!$D$5:$D$63,MATCH(M$3,'D Fleet'!$B$5:$B$63,0)) | N7: – | O7: – | P7: – | Q7: – | R7: –
B8: Pickup | C8: 000s | D8: =INDEX('D Fleet'!$E$5:$E$63,MATCH(D$3,'D Fleet'!$B$5:$B$63,0)) | E8: =INDEX('D Fleet'!$E$5:$E$63,MATCH(E$3,'D Fleet'!$B$5:$B$63,0)) | F8: =INDEX('D Fleet'!$E$5:$E$63,MATCH(F$3,'D Fleet'!$B$5:$B$63,0)) | G8: =INDEX('D Fleet'!$E$5:$E$63,MATCH(G$3,'D Fleet'!$B$5:$B$63,0)) | H8: =INDEX('D Fleet'!$E$5:$E$63,MATCH(H$3,'D Fleet'!$B$5:$B$63,0)) | I8: =INDEX('D Fleet'!$E$5:$E$63,MATCH(I$3,'D Fleet'!$B$5:$B$63,0)) | J8: =INDEX('D Fleet'!$E$5:$E$63,MATCH(J$3,'D Fleet'!$B$5:$B$63,0)) | K8: =INDEX('D Fleet'!$E$5:$E$63,MATCH(K$3,'D Fleet'!$B$5:$B$63,0)) | ... M8: =INDEX('D Fleet'!$E$5:$E$63,MATCH(M$3,'D Fleet'!$B$5:$B$63,0)) | N8: – | O8: – | P8: – | Q8: – | R8: –
B9: Van / minivan | C9: 000s | D9: =INDEX('D Fleet'!$F$5:$F$63,MATCH(D$3,'D Fleet'!$B$5:$B$63,0)) | E9: =INDEX('D Fleet'!$F$5:$F$63,MATCH(E$3,'D Fleet'!$B$5:$B$63,0)) | F9: =INDEX('D Fleet'!$F$5:$F$63,MATCH(F$3,'D Fleet'!$B$5:$B$63,0)) | G9: =INDEX('D Fleet'!$F$5:$F$63,MATCH(G$3,'D Fleet'!$B$5:$B$63,0)) | H9: =INDEX('D Fleet'!$F$5:$F$63,MATCH(H$3,'D Fleet'!$B$5:$B$63,0)) | I9: =INDEX('D Fleet'!$F$5:$F$63,MATCH(I$3,'D Fleet'!$B$5:$B$63,0)) | J9: =INDEX('D Fleet'!$F$5:$F$63,MATCH(J$3,'D Fleet'!$B$5:$B$63,0)) | K9: =INDEX('D Fleet'!$F$5:$F$63,MATCH(K$3,'D Fleet'!$B$5:$B$63,0)) | ... M9: =INDEX('D Fleet'!$F$5:$F$63,MATCH(M$3,'D Fleet'!$B$5:$B$63,0)) | N9: – | O9: – | P9: – | Q9: – | R9: –
B10: Total light vehicles | C10: 000s | D10: =SUM(D6:D9) | E10: =SUM(E6:E9) | F10: =SUM(F6:F9) | G10: =SUM(G6:G9) | H10: =SUM(H6:H9) | I10: =SUM(I6:I9) | J10: =SUM(J6:J9) | K10: =SUM(K6:K9) | ... M10: =SUM(M6:M9) | N10: – | O10: – | P10: – | Q10: – | R10: –
B11: y/y growth | C11: % | D11: – | E11: =E10/D10-1 | F11: =F10/E10-1 | G11: =G10/F10-1 | H11: =H10/G10-1 | I11: =I10/H10-1 | J11: =J10/I10-1 | K11: =K10/J10-1 | L11: =L10/K10-1 | M11: =M10/L10-1 | N11: – | O11: – | P11: – | Q11: – | R11: –
B13: B. Survival stretch (k = 1 is the raw EPA schedule; k > 1 means vehicles last longer)
B14: m(Y): drift multiplier, linear 2013 → 2024, flat after | C14: x | D14: =1+($D$92-1)*MIN(MAX(D$3-2013,0),11)/11 | E14: =1+($D$92-1)*MIN(MAX(E$3-2013,0),11)/11 | F14: =1+($D$92-1)*MIN(MAX(F$3-2013,0),11)/11 | G14: =1+($D$92-1)*MIN(MAX(G$3-2013,0),11)/11 | H14: =1+($D$92-1)*MIN(MAX(H$3-2013,0),11)/11 | I14: =1+($D$92-1)*MIN(MAX(I$3-2013,0),11)/11 | J14: =1+($D$92-1)*MIN(MAX(J$3-2013,0),11)/11 | K14: =1+($D$92-1)*MIN(MAX(K$3-2013,0),11)/11 | ... M14: =1+($D$92-1)*MIN(MAX(M$3-2013,0),11)/11 | N14: – | O14: – | P14: FITTED to two 2024 count anchors (Inputs rows); AGE_CURVES.md §2.4 | Q14: – | R14: –
B15: k_cars(Y) | C15: x | D15: =$D$90*D14 | E15: =$D$90*E14 | F15: =$D$90*F14 | G15: =$D$90*G14 | H15: =$D$90*H14 | I15: =$D$90*I14 | J15: =$D$90*J14 | K15: =$D$90*K14 | ... M15: =$D$90*M14 | N15: – | O15: – | P15: – | Q15: – | R15: –
B16: k_light trucks(Y) | C16: x | D16: =$D$91*D14 | E16: =$D$91*E14 | F16: =$D$91*F14 | G16: =$D$91*G14 | H16: =$D$91*H14 | I16: =$D$91*I14 | J16: =$D$91*J14 | K16: =$D$91*K14 | ... M16: =$D$91*M14 | N16: – | O16: – | P16: – | Q16: – | R16: –
B18: C. Vehicles on the road by age band × body (thousands; from E1a roll)
B19: Car — 0 (current or newer) | C19: 000s | D19: =SUMIFS('E1a Fleet (roll)'!E$7:E$190,'E1a Fleet (roll)'!$A$7:$A$190,"Car",'E1a Fleet (roll)'!$C$7:$C$190,0) | E19: =SUMIFS('E1a Fleet (roll)'!F$7:F$190,'E1a Fleet (roll)'!$A$7:$A$190,"Car",'E1a Fleet (roll)'!$C$7:$C$190,0) | F19: =SUMIFS('E1a Fleet (roll)'!G$7:G$190,'E1a Fleet (roll)'!$A$7:$A$190,"Car",'E1a Fleet (roll)'!$C$7:$C$190,0) | G19: =SUMIFS('E1a Fleet (roll)'!H$7:H$190,'E1a Fleet (roll)'!$A$7:$A$190,"Car",'E1a Fleet (roll)'!$C$7:$C$190,0) | H19: =SUMIFS('E1a Fleet (roll)'!I$7:I$190,'E1a Fleet (roll)'!$A$7:$A$190,"Car",'E1a Fleet (roll)'!$C$7:$C$190,0) | I19: =SUMIFS('E1a Fleet (roll)'!J$7:J$190,'E1a Fleet (roll)'!$A$7:$A$190,"Car",'E1a Fleet (roll)'!$C$7:$C$190,0) | J19: =SUMIFS('E1a Fleet (roll)'!K$7:K$190,'E1a Fleet (roll)'!$A$7:$A$190,"Car",'E1a Fleet (roll)'!$C$7:$C$190,0) | K19: =SUMIFS('E1a Fleet (roll)'!L$7:L$190,'E1a Fleet (roll)'!$A$7:$A$190,"Car",'E1a Fleet (roll)'!$C$7:$C$190,0) | ... M19: =SUMIFS('E1a Fleet (roll)'!N$7:N$190,'E1a Fleet (roll)'!$A$7:$A$190,"Car",'E1a Fleet (roll)'!$C$7:$C$190,0) | N19: – | O19: – | P19: – | Q19: – | R19: –
B20: Car — 1–3 years | C20: 000s | D20: =SUMIFS('E1a Fleet (roll)'!E$7:E$190,'E1a Fleet (roll)'!$A$7:$A$190,"Car",'E1a Fleet (roll)'!$C$7:$C$190,1) | E20: =SUMIFS('E1a Fleet (roll)'!F$7:F$190,'E1a Fleet (roll)'!$A$7:$A$190,"Car",'E1a Fleet (roll)'!$C$7:$C$190,1) | F20: =SUMIFS('E1a Fleet (roll)'!G$7:G$190,'E1a Fleet (roll)'!$A$7:$A$190,"Car",'E1a Fleet (roll)'!$C$7:$C$190,1) | G20: =SUMIFS('E1a Fleet (roll)'!H$7:H$190,'E1a Fleet (roll)'!$A$7:$A$190,"Car",'E1a Fleet (roll)'!$C$7:$C$190,1) | H20: =SUMIFS('E1a Fleet (roll)'!I$7:I$190,'E1a Fleet (roll)'!$A$7:$A$190,"Car",'E1a Fleet (roll)'!$C$7:$C$190,1) | I20: =SUMIFS('E1a Fleet (roll)'!J$7:J$190,'E1a Fleet (roll)'!$A$7:$A$190,"Car",'E1a Fleet (roll)'!$C$7:$C$190,1) | J20: =SUMIFS('E1a Fleet (roll)'!K$7:K$190,'E1a Fleet (roll)'!$A$7:$A$190,"Car",'E1a Fleet (roll)'!$C$7:$C$190,1) | K20: =SUMIFS('E1a Fleet (roll)'!L$7:L$190,'E1a Fleet (roll)'!$A$7:$A$190,"Car",'E1a Fleet (roll)'!$C$7:$C$190,1) | ... M20: =SUMIFS('E1a Fleet (roll)'!N$7:N$190,'E1a Fleet (roll)'!$A$7:$A$190,"Car",'E1a Fleet (roll)'!$C$7:$C$190,1) | N20: – | O20: – | P20: – | Q20: – | R20: –
B21: Car — 4–6 years | C21: 000s | D21: =SUMIFS('E1a Fleet (roll)'!E$7:E$190,'E1a Fleet (roll)'!$A$7:$A$190,"Car",'E1a Fleet (roll)'!$C$7:$C$190,2) | E21: =SUMIFS('E1a Fleet (roll)'!F$7:F$190,'E1a Fleet (roll)'!$A$7:$A$190,"Car",'E1a Fleet (roll)'!$C$7:$C$190,2) | F21: =SUMIFS('E1a Fleet (roll)'!G$7:G$190,'E1a Fleet (roll)'!$A$7:$A$190,"Car",'E1a Fleet (roll)'!$C$7:$C$190,2) | G21: =SUMIFS('E1a Fleet (roll)'!H$7:H$190,'E1a Fleet (roll)'!$A$7:$A$190,"Car",'E1a Fleet (roll)'!$C$7:$C$190,2) | H21: =SUMIFS('E1a Fleet (roll)'!I$7:I$190,'E1a Fleet (roll)'!$A$7:$A$190,"Car",'E1a Fleet (roll)'!$C$7:$C$190,2) | I21: =SUMIFS('E1a Fleet (roll)'!J$7:J$190,'E1a Fleet (roll)'!$A$7:$A$190,"Car",'E1a Fleet (roll)'!$C$7:$C$190,2) | J21: =SUMIFS('E1a Fleet (roll)'!K$7:K$190,'E1a Fleet (roll)'!$A$7:$A$190,"Car",'E1a Fleet (roll)'!$C$7:$C$190,2) | K21: =SUMIFS('E1a Fleet (roll)'!L$7:L$190,'E1a Fleet (roll)'!$A$7:$A$190,"Car",'E1a Fleet (roll)'!$C$7:$C$190,2) | ... M21: =SUMIFS('E1a Fleet (roll)'!N$7:N$190,'E1a Fleet (roll)'!$A$7:$A$190,"Car",'E1a Fleet (roll)'!$C$7:$C$190,2) | N21: – | O21: – | P21: – | Q21: – | R21: –
